Workbook
Name ALU_CLK: CPU!$H$60
Name ALU_HIGH16b: CPU!$L$68
Name ALU_LOW16b: CPU!$J$68
Name ALU_OP: CPU!$N$60
Name ALU_OPERAND1: CPU!$P$60
Name ALU_OPERAND1_VAL: CPU!$L$64
Name ALU_OPERAND2: CPU!$K$60
Name ALU_OPERAND2_VAL: CPU!$N$64
Name ALU_OUTPUT1: CPU!$L$65
Name ALU_OUTPUT2: CPU!$N$65
Name CLOCK: CPU!$J$2
Name CU_16b_VAL: CPU!$J$30
Name CU_2_4B_Inst: CPU!$AJ$30
Name CU_ALU_OP: CPU!$N$30
Name CU_CLK: CPU!$F$22
Name CU_INST: CPU!$H$22
Name CU_INST_16b_VAL: CPU!$O$25
Name CU_INST_BUS: CPU!$I$22
Name CU_INST_REG1: CPU!$M$25
Name CU_INST_REG2: CPU!$N$25
Name CU_L_H_16b: CPU!$V$30
Name CU_MEMR: CPU!$AD$30
Name CU_MEMW: CPU!$AB$30
Name CU_MUX_SEL: CPU!$H$30
Name CU_OPCODE: CPU!$K$25
Name CU_PC_SET_IMD: CPU!$AL$30
Name CU_REG1ID: CPU!$P$30
Name CU_REG1W: CPU!$X$30
Name CU_REG2ID: CPU!$L$30
Name CU_REG2W: CPU!$Z$30
Name DISPLAY_RAM: CPU!$A$556:$DX$651
Name FLAGS_CF: CPU!$N$109
Name FLAGS_OF: CPU!$N$112
Name FLAGS_SF: CPU!$N$111
Name FLAGS_ZF: CPU!$N$110
Name FU_CLK: CPU!$F$11
Name FU_INST: CPU!$I$16
Name FU_INST_OUT: CPU!$H$18
Name FU_PC: CPU!$K$11
Name FU_PC_INST_H1: CPU!$I$14
Name FU_PC_INST_H2: CPU!$I$15
Name InstSets_2_4_INST: InstructSets!$Q:$Q
Name InstSets_ALU_OP: InstructSets!$K:$K
Name InstSets_LH_16b: InstructSets!$P:$P
Name InstSets_MEMR: InstructSets!$S:$S
Name InstSets_MEMW: InstructSets!$R:$R
Name InstSets_MUX_SEL: InstructSets!$L:$L
Name InstSets_OPCODE: InstructSets!$B:$B
Name InstSets_OPName: InstructSets!$C:$C
Name InstSets_PC_SET_IMD: InstructSets!$O:$O
Name InstSets_REG1W: InstructSets!$M:$M
Name InstSets_REG2W: InstructSets!$N:$N
Name LOAD_ROM: CPU!$V$2
Name MANUAL: CPU!$Z$2
Name MMU_ADDR: CPU!$AF$133
Name MMU_CLK: CPU!$X$133
Name MMU_LOAD_ROM: CPU!$AJ$133
Name MMU_MEMR: CPU!$AD$133
Name MMU_MEMW: CPU!$AB$133
Name MMU_RAM_X: CPU!$AF$137

Sheet CPU
F2: 0 | G2: POWER | J2: =IF(NOT(POWER),0,INT(NOT(CLOCK))) -> 0 | K2: CLOCK | N2: =IF(NOT(POWER),0,IF(CLOCK=1,TICK+1,TICK)) -> 0 | O2: TICK | R2: 0 | S2: RESET | V2: 0 | W2: LOAD_ROM | Z2: 0 | AA2: BOOT_PC | AD2: 16 | AE2: WORD_SIZE
F11: =CLOCK -> 0 | H11: =MANUAL -> 0 | K11: =IF(NOT(POWER),0,PC_NEXT) -> 0
F12: CLK | H12: MANUAL | K12: PC
G14: [PC] | I14: =IF(NOT(POWER),0,OFFSET(RAM0,FLOOR(FU_PC/COLUMNS(RAM),1),MOD(FU_PC,COLUMNS(RAM)))) -> 0 | L14: Fetch Unit
G15: [PC+1] | I15: =IF(NOT(POWER),0,OFFSET(RAM0,FLOOR((FU_PC+1)/COLUMNS(RAM),1),MOD((FU_PC+1),COLUMNS(RAM)))) -> 0
G16: INST | I16: =DEC2HEX(_xlfn.BITLSHIFT(FU_PC_INST_H1,16)+FU_PC_INST_H2) -> 0
H17: INST BUS
H18: =IF(NOT(POWER),0,IF(NOT(FU_CLK),FU_INST_OUT,HEX2DEC(FU_INST))) -> 0
F22: =CLOCK -> 0 | H22: =FU_INST_OUT -> 0
F23: CLK | H23: INST BUS
K24: OPCODE | M24: REG1 | N24: REG2 | O24: INST 16b VAL
K25: =_xlfn.BITRSHIFT(CU_INST,32-8) -> 0 | M25: =MOD(_xlfn.BITRSHIFT(CU_INST,16+4),POWER(2,4)) -> 0 | N25: =MOD(_xlfn.BITRSHIFT(CU_INST,16),POWER(2,4)) -> 0 | O25: =MOD(CU_INST,POWER(2,16)) -> 0 | AA25: Control Unit
K26: =DEC2BIN(CU_OPCODE) -> 0 | M26: =DEC2BIN(CU_INST_REG1) -> 0 | N26: =DEC2BIN(CU_INST_REG2) -> 0 | O26: =DEC2HEX(CU_INST_16b_VAL) -> 0
K27: =IF(NOT(POWER),"",INDEX(InstSets_OPName,MATCH(CU_OPCODE,InstSets_OPCODE,0))) | M27: =IF(OR(AND(CU_OPCODE>3,CU_OPCODE<22),CU_OPCODE=25),"R"&CU_INST_REG1,"") | N27: =IF(CU_OPCODE<7,DEC2HEX(CU_INST_16b_VAL),IF(OR(AND(CU_OPCODE>6,CU_OPCODE<13),AND(CU_OPCODE>14,CU_OPCODE<18),CU_OPCODE=25,CU_OPCODE=21),CU_INST_REG2,"")) -> 0
H29: MUX SEL | J29: 16b VAL | L29: REG2ID | N29: ALU_OP | P29: REG1ID | V29: L/H 16b | X29: REG1W | Z29: REG2W | AB29: MEMW | AD29: MEMR | AJ29: 2/4B Inst | AL29: PC SET IMD | AN29: OPCODE
H30: =IF(NOT(POWER),0,IF(NOT(CU_CLK),CU_MUX_SEL,INDEX(InstSets_MUX_SEL,MATCH(CU_OPCODE,InstSets_OPCODE,0)))) -> 0 | J30: =IF(NOT(POWER),0,IF(NOT(CU_CLK),CU_16b_VAL,CU_INST_16b_VAL)) -> 0 | L30: =IF(NOT(POWER),0,IF(CU_CLK,CU_INST_REG2,CU_REG2ID)) -> 0 | N30: =IF(NOT(POWER),0,IF(NOT(CU_CLK),CU_ALU_OP,INDEX(InstSets_ALU_OP,MATCH(CU_OPCODE,InstSets_OPCODE,0)))) -> 0 | P30: =IF(NOT(POWER),0,IF(CU_CLK,CU_INST_REG1,CU_REG1ID)) -> 0 | V30: =IF(NOT(POWER),0,IF(NOT(CU_CLK),CU_L_H_16b,INDEX(InstSets_LH_16b,MATCH(CU_OPCODE,InstSets_OPCODE,0)))) -> 0 | X30: =IF(NOT(POWER),0,IF(CU_CLK,INDEX(InstSets_REG1W,MATCH(CU_OPCODE,InstSets_OPCODE,0)),CU_REG1W)) -> 0 | Z30: =IF(NOT(POWER),0,IF(CU_CLK,INDEX(InstSets_REG2W,MATCH(CU_OPCODE,InstSets_OPCODE,0)),CU_REG2W)) -> 0 | AB30: =IF(NOT(POWER),0,IF(NOT(CU_CLK),CU_MEMW,INDEX(InstSets_MEMW,MATCH(CU_OPCODE,InstSets_OPCODE,0)))) -> 0 | AD30: =IF(NOT(POWER),0,IF(NOT(CU_CLK),CU_MEMR,INDEX(InstSets_MEMR,MATCH(CU_OPCODE,InstSets_OPCODE,0)))) -> 0 | AJ30: =IF(NOT(POWER),0,IF(NOT(CU_CLK),CU_2_4B_Inst,INDEX(InstSets_2_4_INST,MATCH(CU_OPCODE,InstSets_OPCODE,0)))) -> 0 | AL30: =IF(NOT(POWER),0,IF(NOT(CU_CLK),CU_PC_SET_IMD,INDEX(InstSets_PC_SET_IMD,MATCH(CU_OPCODE,InstSets_OPCODE,0)))) -> 0 | AN30: =IF(NOT(POWER),0,IF(NOT(CU_CLK),CU_OPCODE,CU_OPCODE)) -> 0
F34: =CLOCK -> 0 | H34: =CU_MUX_SEL -> 0 | J34: =CU_16b_VAL -> 0 | L34: =CU_REG2ID -> 0
F35: CLK | H35: MUX_SEL | J35: 16b VAL | L35: REG2ID
F37: 0 | G37: REG2 | H37: [REG2] | I37: IMD 4b | J37: IMD 16b | K37: MEM VAL
F38: 0 | G38: =OFFSET(REG_R0,MUX1_REG2ID,0) -> 0 | H38: =IF(NOT(POWER),0,OFFSET(RAM0,FLOOR(MUX1_REG2_VAL/COLUMNS(RAM),1),MOD(MUX1_REG2_VAL,COLUMNS(RAM)))) -> 0 | I38: =MUX1_REG2ID -> 0 | J38: =MUX1_16b_VAL -> 0 | K38: =IF(NOT(POWER),0,OFFSET(RAM0,FLOOR(MUX1_IMD_16b/COLUMNS(RAM0),1),MOD(MUX1_IMD_16b,COLUMNS(RAM0)))) -> 0
H39: MUX1
K40: OPERAND2
K41: =IF(NOT(POWER),0,IF(NOT(MUX1_CLK),MUX1_OPERAND2,OFFSET(MUX1_0,0,MUX1_MUX_SEL))) -> 0
AF47: =CLOCK -> 0 | AH47: =MUX1_OPERAND2 -> 0 | AJ47: =CU_2_4B_Inst -> 0 | AL47: =CU_PC_SET_IMD -> 0 | AN47: =CU_OPCODE -> 0
AF48: CLK | AH48: OPERAND2 | AJ48: 2/4B INST | AL48: PC_SET_IMD | AN48: OPCODE
AG50: IMMEDIATE | AI50: PC LAST | AK50: PC LAST +1 | AM50: PC IMD
AG51: =IF(NOT(POWER),0,INT(AND(PC_PC_SET_IMD,OR(PC_OPCODE=0,AND(PC_OPCODE=1,FLAGS_ZF),AND(PC_OPCODE=2,NOT(FLAGS_CF)),AND(PC_OPCODE=3,OR(FLAGS_CF,FLAGS_ZF)))))) -> 0 | AI51: =IF(NOT(POWER),0,IF(NOT(PC_CLK),PC_NEXT,PC_LAST)) -> 0 | AK51: =IF(NOT(POWER),0,IF(PC_CLK,PC_LAST+1+PC_2_4B_INST,PC_TMP)) -> 0 | AM51: =PC_OPERAND2 -> 0
AG53: 程序计数器(PC)
AK54: PC NEXT
AK55: =IF(NOT(POWER),0,IF(NOT(PC_CLK),PC_NEXT,IF(PC_IMMEDIATE,PC_OPERAND2,PC_TMP))) -> 0
H60: =CLOCK -> 0 | K60: =MUX1_OPERAND2 -> 0 | N60: =CU_ALU_OP -> 0 | P60: =CU_REG1ID -> 0
H61: CLK | K61: OPERAND2 | N61: OP | P61: REG1
I63: ALU | J63: OP | L63: OPERAND1 | N63: OPERAND2
J64: =INDEX(InstructSets!C:C,MATCH(CU_OPCODE,InstructSets!B:B)) -> JMP | L64: =OFFSET(REG_R0,ALU_OPERAND1,0) -> 0 | N64: =ALU_OPERAND2 -> 0
J65: OUTPUT | L65: =IF(NOT(POWER),0, IF(NOT(ALU_CLK),ALU_OUTPUT1, IF(ALU_OP=0,ALU_OPERAND1_VAL+ALU_OPERAND2_VAL+FLAGS_CF, IF(ALU_OP=1,ALU_OPERAND1_VAL-ALU_OPERAND2_VAL-FLAGS_CF, IF(ALU_OP=2,ALU_OPERAND1_VAL*ALU_OPERAND2_VAL, IF(ALU_OP=3,FLOOR(ALU_OPERAND1_VAL/ALU_OPERAND2_VAL,1), IF(ALU_OP=4,ALU_OPERAND1_VAL+1, IF(ALU_OP=5,ALU_OPERAND1_VAL-1, IF(ALU_OP=6,_xlfn.BITAND(ALU_OPERAND1_VAL,ALU_OPERAND2_VAL), IF(ALU_OP=7,_xlfn.BITOR(ALU_OPERAND1_VAL,ALU_OPERAND2_VAL), IF(ALU_OP=8,_xlfn.BITXOR(ALU_OPERAND1_VAL,ALU_OPERAND2_VAL), IF(ALU_OP=9,BITNOT(ALU_OPERAND1_VAL), IF(ALU_OP=10,_xlfn.BITLSHIFT(ALU_OPERAND1_VAL,ALU_OPERAND2_VAL), IF(ALU_OP=11,_xlfn.BITRSHIFT(ALU_OPERAND1_VAL,ALU_OPERAND2_VAL), ALU_OUTPUT1 )))))))))))))) -> 0 | N65: =IF(NOT(POWER),0,IF(NOT(ALU_CLK),ALU_OUTPUT2,IF(ALU_OP=15,ALU_OPERAND2_VAL,IF(ALU_OP=12,ALU_OPERAND1_VAL,IF(ALU_OP=2,FLOOR((ALU_OPERAND1_VAL*ALU_OPERAND2_VAL)/POWER(2,16),1),IF(ALU_OP=3,MOD(ALU_OPERAND1_VAL,ALU_OPERAND2_VAL),0)))))) -> 0
J67: LOW16 | L67: HIGH16
J68: =IF(NOT(POWER),0,IF(NOT(ALU_CLK),ALU_LOW16b,MOD(ALU_OUTPUT1,POWER(2,16)))) -> 0 | L68: =IF(NOT(POWER),0,IF(NOT(ALU_CLK),ALU_HIGH16b,ALU_OUTPUT2)) -> 0
F73: =CLOCK -> 0 | J73: =ALU_LOW16b -> 0 | L73: =ALU_HIGH16b -> 0 | N73: =CU_L_H_16b -> 0
F74: CLK | J74: LOW16b | L74: HIGH16b | N74: L/H 16b
F76: MUX2
...

Sheet InstructSets
A1: OPCODE | C1: 8b | D1: 4b | E1: 4b | F1: 16b | G1: 32b/16b | H1: OPERATION | K1: ALU OP | L1: MUX SEL | M1: REG1W | N1: REG2W | O1: PC SET IMD | P1: L/H 16b | Q1: 2/4 INST | R1: MEMW | S1: MEMR | T1: ALU_OP_RES | U1: OUT_LOW16 | V1: OUT_HIGH16 | W1: CF | X1: ZF | Y1: SF | Z1: OF | AA1: OP2Pre | AB1: 备注 | AC1: TECHNICAL NOTES
A2: 00 | B2: 0 | C2: JMP | F2: IMD | G2: 32b | H2: IMD -> PC | K2: 15 | L2: 4 | M2: 0 | N2: 0 | O2: 1 | P2: 0 | Q2: 1 | R2: 0 | S2: 0 | T2: =ALU_OPERAND2_VAL -> 0 | U2: =ALU_OPERAND2_VAL -> 0 | V2: =ALU_OPERAND2_VAL -> 0 | W2: =FLAGS_CF -> 0 | X2: =FLAGS_ZF -> 0 | Y2: =FLAGS_SF -> 0 | Z2: =FLAGS_OF -> 0 | AA2: # | AB2: 将PC设为MUX输出的OPRAND2立即值 | AC2: PC SET TO IMMEDIATE VALUE VIA THE OPERAND 2 OUTPUT SELECTED BY THE MUX
A3: 01 | B3: 1 | C3: JEQ | F3: IMD | H3: IF Z = 1, IMD -> PC | K3: 15 | L3: 4 | M3: 0 | N3: 0 | O3: 1 | P3: 0 | Q3: 1 | R3: 0 | S3: 0 | T3: =ALU_OPERAND2_VAL -> 0 | U3: =ALU_OPERAND2_VAL -> 0 | V3: =ALU_OPERAND2_VAL -> 0 | W3: =FLAGS_CF -> 0 | X3: =FLAGS_ZF -> 0 | Y3: =FLAGS_SF -> 0 | Z3: =FLAGS_OF -> 0 | AB3: 当ZF(零标志符)为1时跳转 | AC3: JMP IF THE ZERO FLAG IS TRUE
A4: 02 | B4: 2 | C4: JLT | F4: IMD | H4: IF C = 0, IMD -> PC | K4: 15 | L4: 4 | M4: 0 | N4: 0 | O4: 1 | P4: 0 | Q4: 1 | R4: 0 | S4: 0 | T4: =ALU_OPERAND2_VAL -> 0 | U4: =ALU_OPERAND2_VAL -> 0 | V4: =ALU_OPERAND2_VAL -> 0 | W4: =FLAGS_CF -> 0 | X4: =FLAGS_ZF -> 0 | Y4: =FLAGS_SF -> 0 | Z4: =FLAGS_OF -> 0 | AB4: 当CF(进位标志符)为0时跳转 | AC4: JMP IF CARRY FLAG IS FALSE
A5: 03 | B5: 3 | C5: JGE | F5: IMD | H5: IF C = 1 OR Z = 1, IMD -> PC | K5: 15 | L5: 4 | M5: 0 | N5: 0 | O5: 1 | P5: 0 | Q5: 1 | R5: 0 | S5: 0 | T5: =ALU_OPERAND2_VAL -> 0 | U5: =ALU_OPERAND2_VAL -> 0 | V5: =ALU_OPERAND2_VAL -> 0 | W5: =FLAGS_CF -> 0 | X5: =FLAGS_ZF -> 0 | Y5: =FLAGS_SF -> 0 | Z5: =FLAGS_OF -> 0 | AB5: 当CF或ZF为1时跳转 | AC5: JMP IF CARRY FLAG OR ZERO FLAG IS TRUE
A6: 04 | B6: 4 | C6: LOAD | D6: REG | F6: MEM | H6: [MEM] -> REGA | K6: 15 | L6: 5 | M6: 1 | N6: 0 | O6: 0 | P6: 1 | Q6: 1 | R6: 0 | S6: 1 | T6: =ALU_OPERAND2_VAL -> 0 | U6: =ALU_OPERAND2_VAL -> 0 | V6: =ALU_OPERAND2_VAL -> 0 | W6: =FLAGS_CF -> 0 | X6: =FLAGS_ZF -> 0 | Y6: =FLAGS_SF -> 0 | Z6: =FLAGS_OF -> 0 | AA6: @ | AB6: 将寄存器Ra设置为立即数值代表的地址所的内存值 | AC6: SETS THE REGISTER TO THE MEMORY VALUE OF IMMEDIATE ADDRESS
A7: 05 | B7: 5 | C7: LOAD | D7: REG | F7: IMD | H7: IMD -> REGA | K7: 15 | L7: 4 | M7: 1 | N7: 0 | O7: 0 | P7: 1 | Q7: 1 | R7: 0 | S7: 0 | T7: =ALU_OPERAND2_VAL -> 0 | U7: =ALU_OPERAND2_VAL -> 0 | V7: =ALU_OPERAND2_VAL -> 0 | W7: =FLAGS_CF -> 0 | X7: =FLAGS_ZF -> 0 | Y7: =FLAGS_SF -> 0 | Z7: =FLAGS_OF -> 0 | AA7: @ | AB7: 将寄存器设置为立即数 | AC7: SETS THE REGISTER TO THE IMMEDIATE VALUE
A8: 06 | B8: 6 | C8: STORE | D8: REG | F8: MEM | H8: REGA -> [MEM] | K8: 12 | L8: 4 | M8: 0 | N8: 0 | O8: 0 | P8: 0 | Q8: 1 | R8: 1 | S8: 0 | T8: =ALU_OPERAND1_VAL -> 0 | U8: =IF(CU_OPCODE=B8,MOD(T8,POWER(2,16)),ALU_OPERAND1_VAL) -> 0 | V8: =ALU_OPERAND1_VAL -> 0 | W8: =IF(CU_OPCODE=B8,INT(OR(T8<0,T8>POWER(2,16))),FLAGS_CF) -> 0 | X8: =IF(CU_OPCODE=B8,INT(U8=0),FLAGS_ZF) -> 0 | Y8: =INT(U8>=POWER(2,15)) -> 0 | Z8: =INT(OR(AND(ALU_OPERAND1_VAL<POWER(2,15),ALU_OPERAND2_VAL<POWER(2,15),U8>=POWER(2,15)),AND(ALU_OPERAND1_VAL>=POWER(2,15),ALU_OPERAND2_VAL>=POWER(2,15),T8<POWER(2,15)))) -> 0 | AC8: SETS THE MEMORY VALUE OF THE IMMEDIATE ADDRESS TO THE REG VALUE
A9: 07 | B9: 7 | C9: STORE | D9: REG | E9: REG | G9: 16b | H9: REGA -> [REGB] | K9: 12 | L9: 1 | M9: 0 | N9: 0 | O9: 0 | P9: 0 | Q9: 0 | R9: 1 | S9: 0 | T9: =ALU_OPERAND1_VAL -> 0 | U9: =IF(CU_OPCODE=B9,MOD(T9,POWER(2,16)),ALU_OPERAND1_VAL) -> 0 | V9: =ALU_OPERAND1_VAL -> 0 | W9: =IF(CU_OPCODE=B9,INT(OR(T9<0,T9>POWER(2,16))),FLAGS_CF) -> 0 | X9: =IF(CU_OPCODE=B9,INT(U9=0),FLAGS_ZF) -> 0 | Y9: =INT(U9>=POWER(2,15)) -> 0 | Z9: =INT(OR(AND(ALU_OPERAND1_VAL<POWER(2,15),ALU_OPERAND2_VAL<POWER(2,15),U9>=POWER(2,15)),AND(ALU_OPERAND1_VAL>=POWER(2,15),ALU_OPERAND2_VAL>=POWER(2,15),T9<POWER(2,15)))) -> 0 | AC9: SETS THE MEMORY VALUE AT THE REGB ADDRESS TO THE VALUE OF REGA
A10: 08 | B10: 8 | C10: TRAN | D10: REG | E10: REG | H10: REGA -> REGB | K10: 12 | L10: 1 | M10: 0 | N10: 1 | O10: 0 | P10: 0 | Q10: 0 | R10: 0 | S10: 0 | T10: =ALU_OPERAND2_VAL -> 0 | U10: =IF(CU_OPCODE=B10,MOD(T10,POWER(2,16)),ALU_OPERAND1_VAL) -> 0 | V10: =ALU_OPERAND1_VAL -> 0 | W10: =IF(CU_OPCODE=B10,INT(OR(T10<0,T10>POWER(2,16))),FLAGS_CF) -> 0 | X10: =IF(CU_OPCODE=B10,INT(U10=0),FLAGS_ZF) -> 0 | Y10: =INT(U10>=POWER(2,15)) -> 0 | Z10: =INT(OR(AND(ALU_OPERAND1_VAL<POWER(2,15),ALU_OPERAND2_VAL<POWER(2,15),U10>=POWER(2,15)),AND(ALU_OPERAND1_VAL>=POWER(2,15),ALU_OPERAND2_VAL>=POWER(2,15),T10<POWER(2,15)))) -> 0 | AC10: TRANSFERS REGA VALUE TO REGB
A11: 09 | B11: 9 | C11: ADD | D11: REG | E11: REG | H11: REGA + REGB + C -> REGA | K11: 0 | L11: 1 | M11: 1 | N11: 0 | O11: 0 | P11: 0 | Q11: 0 | R11: 0 | S11: 0 | T11: =ALU_OPERAND1_VAL+ALU_OPERAND2_VAL+FLAGS_CF -> 0 | U11: =IF(CU_OPCODE=B11,MOD(T11,POWER(2,16)),ALU_OPERAND1_VAL) -> 0 | V11: 0 | W11: =IF(CU_OPCODE=B11,INT(OR(T11<0,T11>POWER(2,16))),FLAGS_CF) -> 0 | X11: =IF(CU_OPCODE=B11,INT(U11=0),FLAGS_ZF) -> 0 | Y11: =INT(U11>=POWER(2,15)) -> 0 | Z11: =INT(OR(AND(ALU_OPERAND1_VAL<POWER(2,15),ALU_OPERAND2_VAL<POWER(2,15),U11>=POWER(2,15)),AND(ALU_OPERAND1_VAL>=POWER(2,15),ALU_OPERAND2_VAL>=POWER(2,15),T11<POWER(2,15)))) -> 0 | AC11: ADDS REGA, REGB AND CARRY FLAG, RESULT STORED IN REGA
A12: 0A | B12: 10 | C12: SUB | D12: REG | E12: REG | H12: REGA - REGB - C -> REGA | K12: 1 | L12: 1 | M12: 1 | N12: 0 | O12: 0 | P12: 0 | Q12: 0 | R12: 0 | S12: 0 | T12: =ALU_OPERAND1_VAL-ALU_OPERAND2_VAL-FLAGS_CF -> 0 | U12: =IF(CU_OPCODE=B12,MOD(T12,POWER(2,16)),ALU_OPERAND1_VAL) -> 0 | V12: 0 | W12: =IF(CU_OPCODE=B12,INT(OR(T12<0,T12>POWER(2,16))),FLAGS_CF) -> 0 | X12: =IF(CU_OPCODE=B12,INT(U12=0),FLAGS_ZF) -> 0 | Y12: =INT(U12>=POWER(2,15)) -> 0 | Z12: =INT(OR(AND(ALU_OPERAND1_VAL<POWER(2,15),ALU_OPERAND2_VAL<POWER(2,15),U12>=POWER(2,15)),AND(ALU_OPERAND1_VAL>=POWER(2,15),ALU_OPERAND2_VAL>=POWER(2,15),T12<POWER(2,15)))) -> 0 | AC12: SUBTRACTS REGA, REGB, AND CARRY FLAG, RESULT STORED IN REGA
A13: 0B | B13: 11 | C13: MULT | D13: REG | E13: REG | H13: REGA * REGB -> low 16 in REGA, high 16 in REGB | K13: 2 | L13: 1 | M13: 1 | N13: 1 | O13: 0 | P13: 0 | Q13: 0 | R13: 0 | S13: 0 | T13: =MOD(ALU_OPERAND1_VAL*ALU_OPERAND2_VAL,POWER(2,16)) -> 0 | U13: =IF(CU_OPCODE=B13,MOD(T13,POWER(2,16)),ALU_OPERAND1_VAL) -> 0 | V13: =_xlfn.FLOOR.MATH(ALU_OPERAND1_VAL*ALU_OPERAND2_VAL/POWER(2,16)) -> 0 | W13: =IF(CU_OPCODE=B13,INT(OR(T13<0,T13>POWER(2,16))),FLAGS_CF) -> 0 | X13: =IF(CU_OPCODE=B13,INT(U13=0),FLAGS_ZF) -> 0 | Y13: =INT(U13>=POWER(2,15)) -> 0 | Z13: =INT(OR(AND(ALU_OPERAND1_VAL<POWER(2,15),ALU_OPERAND2_VAL<POWER(2,15),U13>=POWER(2,15)),AND(ALU_OPERAND1_VAL>=POWER(2,15),ALU_OPERAND2_VAL>=POWER(2,15),T13<POWER(2,15)))) -> 0 | AC13: MULTIPLIED REGA AND REGB, LOWER 16b RESULT STORED IN REGA, HIGH 16b RESULT STORED IN REGB
A14: 0C | B14: 12 | C14: DIV | D14: REG | E14: REG | H14: REGA / REGB -> result in REGA, MOD in 16 in REGB | K14: 3 | L14: 1 | M14: 1 | N14: 1 | O14: 0 | P14: 0 | Q14: 0 | R14: 0 | S14: 0 | T14: =IF(ALU_OPERAND2_VAL<>0,_xlfn.FLOOR.MATH(ALU_OPERAND1_VAL/ALU_OPERAND2_VAL),0) -> 0 | U14: =IF(CU_OPCODE=B14,MOD(T14,POWER(2,16)),ALU_OPERAND1_VAL) -> 0 | V14: =IF(ALU_OPERAND2_VAL<>0,MOD(ALU_OPERAND1_VAL,ALU_OPERAND2_VAL),0) -> 0 | W14: =IF(CU_OPCODE=B14,INT(OR(T14<0,T14>POWER(2,16))),FLAGS_CF) -> 0 | X14: =IF(CU_OPCODE=B14,INT(U14=0),FLAGS_ZF) -> 0 | Y14: =INT(U14>=POWER(2,15)) -> 0 | Z14: =INT(OR(AND(ALU_OPERAND1_VAL<POWER(2,15),ALU_OPERAND2_VAL<POWER(2,15),U14>=POWER(2,15)),AND(ALU_OPERAND1_VAL>=POWER(2,15),ALU_OPERAND2_VAL>=POWER(2,15),T14<POWER(2,15)))) -> 0 | AC14: DIVIDES REGA BY REGB, RESULT STORED IN REGA, MODULUS RESULT STORED IN REGB
A15: 0D | B15: 13 | C15: INC | D15: REG | H15: REGA + 1 -> REGA (FLAGS not affected) | K15: 4 | L15: 0 | M15: 1 | N15: 0 | O15: 0 | P15: 0 | Q15: 0 | R15: 0 | S15: 0 | T15: =ALU_OPERAND1_VAL+1 -> 1 | U15: =IF(CU_OPCODE=B15,MOD(T15,POWER(2,16)),ALU_OPERAND1_VAL) -> 0 | V15: =ALU_OPERAND2_VAL -> 0 | W15: =IF(CU_OPCODE=B15,INT(OR(T15<0,T15>POWER(2,16))),FLAGS_CF) -> 0 | X15: =IF(CU_OPCODE=B15,INT(U15=0),FLAGS_ZF) -> 0 | Y15: =INT(U15>=POWER(2,15)) -> 0 | Z15: =INT(OR(AND(ALU_OPERAND1_VAL<POWER(2,15),ALU_OPERAND2_VAL<POWER(2,15),U15>=POWER(2,15)),AND(ALU_OPERAND1_VAL>=POWER(2,15),ALU_OPERAND2_VAL>=POWER(2,15),T15<POWER(2,15)))) -> 0 | AC15: INCREASES REGA VALUE, CARRY FLAG NOT AFFECTED
A16: 0E | B16: 14 | C16: DEC | D16: REG | H16: REGA - 1 -> REGA (FLAGS not affected) | K16: 5 | L16: 0 | M16: 1 | N16: 0 | O16: 0 | P16: 0 | Q16: 0 | R16: 0 | S16: 0 | T16: =IF(CU_OPCODE=B16,ALU_OPERAND2_VAL-1,T16) -> -1 | U16: =IF(CU_OPCODE=B16,MOD(T16,POWER(2,16)),ALU_OPERAND1_VAL) -> 0 | V16: =ALU_OPERAND2_VAL -> 0 | W16: =IF(CU_OPCODE=B16,INT(OR(T16<0,T16>POWER(2,16))),FLAGS_CF) -> 0 | X16: =IF(CU_OPCODE=B16,INT(U16=0),FLAGS_ZF) -> 0 | Y16: =INT(U16>=POWER(2,15)) -> 0 | Z16: =INT(OR(AND(ALU_OPERAND1_VAL<POWER(2,15),ALU_OPERAND2_VAL<POWER(2,15),U16>=POWER(2,15)),AND(ALU_OPERAND1_VAL>=POWER(2,15),ALU_OPERAND2_VAL>=POWER(2,15),T16<POWER(2,15)))) -> 0 | AC16: DECREASES REGA VALUE, CARRY FLAG NOT AFFECTED
A17: 0F | B17: 15 | C17: AND | D17: REG | E17: REG | H17: REGA AND REGB -> REGA | K17: 6 | L17: 1 | M17: 1 | N17: 0 | O17: 0 | P17: 0 | Q17: 0 | R17: 0 | S17: 0 | T17: =INT(AND(ALU_OPERAND1_VAL,ALU_OPERAND2_VAL)) -> 0 | U17: =IF(CU_OPCODE=B17,MOD(T17,POWER(2,16)),ALU_OPERAND1_VAL) -> 0 | V17: =ALU_OPERAND2_VAL -> 0 | W17: =IF(CU_OPCODE=B17,INT(OR(T17<0,T17>POWER(2,16))),FLAGS_CF) -> 0 | X17: =IF(CU_OPCODE=B17,INT(U17=0),FLAGS_ZF) -> 0 | Y17: =INT(U17>=POWER(2,15)) -> 0 | Z17: =INT(OR(AND(ALU_OPERAND1_VAL<POWER(2,15),ALU_OPERAND2_VAL<POWER(2,15),U17>=POWER(2,15)),AND(ALU_OPERAND1_VAL>=POWER(2,15),ALU_OPERAND2_VAL>=POWER(2,15),T17<POWER(2,15)))) -> 0 | AC17: BITWISE AND OF REGA AND REGB, RESULT STORED IN REGA
A18: 10 | B18: 16 | C18: OR | D18: REG | E18: REG | H18: REGA OR REGB -> REGA | K18: 7 | L18: 1 | M18: 1 | N18: 0 | O18: 0 | P18: 0 | Q18: 0 | R18: 0 | S18: 0 | T18: =INT(OR(ALU_OPERAND1_VAL,ALU_OPERAND2_VAL)) -> 0 | U18: =IF(CU_OPCODE=B18,MOD(T18,POWER(2,16)),ALU_OPERAND1_VAL) -> 0 | V18: =ALU_OPERAND2_VAL -> 0 | W18: =IF(CU_OPCODE=B18,INT(OR(T18<0,T18>POWER(2,16))),FLAGS_CF) -> 0 | X18: =IF(CU_OPCODE=B18,INT(U18=0),FLAGS_ZF) -> 0 | Y18: =INT(U18>=POWER(2,15)) -> 0 | Z18: =INT(OR(AND(ALU_OPERAND1_VAL<POWER(2,15),ALU_OPERAND2_VAL<POWER(2,15),U18>=POWER(2,15)),AND(ALU_OPERAND1_VAL>=POWER(2,15),ALU_OPERAND2_VAL>=POWER(2,15),T18<POWER(2,15)))) -> 0 | AC18: BITWISE OR OF REGA AND REGB, RESULT STORED IN REGA
A19: 11 | B19: 17 | C19: XOR | D19: REG | E19: REG | H19: REGA XOR REGB -> REGA | K19: 8 | L19: 1 | M19: 1 | N19: 0 | O19: 0 | P19: 0 | Q19: 0 | R19: 0 | S19: 0 | T19: =INT(_xlfn.XOR(ALU_OPERAND1_VAL,ALU_OPERAND2_VAL)) -> 0 | U19: =IF(CU_OPCODE=B19,MOD(T19,POWER(2,16)),ALU_OPERAND1_VAL) -> 0 | V19: =ALU_OPERAND2_VAL -> 0 | W19: =IF(CU_OPCODE=B19,INT(OR(T19<0,T19>POWER(2,16))),FLAGS_CF) -> 0 | X19: =IF(CU_OPCODE=B19,INT(U19=0),FLAGS_ZF) -> 0 | Y19: =INT(U19>=POWER(2,15)) -> 0 | Z19: =INT(OR(AND(ALU_OPERAND1_VAL<POWER(2,15),ALU_OPERAND2_VAL<POWER(2,15),U19>=POWER(2,15)),AND(ALU_OPERAND1_VAL>=POWER(2,15),ALU_OPERAND2_VAL>=POWER(2,15),T19<POWER(2,15)))) -> 0 | AC19: BITWISE XOR OF REGA AND REGB, RESULT STORED IN REGA
A20: 12 | B20: 18 | C20: NOT | D20: REG | H20: NOT REGA -> REGA | K20: 9 | L20: 0 | M20: 1 | N20: 0 | O20: 0 | P20: 0 | Q20: 0 | R20: 0 | S20: 0 | T20: =INT(NOT(ALU_OPERAND1_VAL)) -> 1 | U20: =IF(CU_OPCODE=B20,MOD(T20,POWER(2,16)),ALU_OPERAND1_VAL) -> 0 | V20: =ALU_OPERAND2_VAL -> 0 | W20: =IF(CU_OPCODE=B20,INT(OR(T20<0,T20>POWER(2,16))),FLAGS_CF) -> 0 | X20: =IF(CU_OPCODE=B20,INT(U20=0),FLAGS_ZF) -> 0 | Y20: =INT(U20>=POWER(2,15)) -> 0 | Z20: =INT(OR(AND(ALU_OPERAND1_VAL<POWER(2,15),ALU_OPERAND2_VAL<POWER(2,15),U20>=POWER(2,15)),AND(ALU_OPERAND1_VAL>=POWER(2,15),ALU_OPERAND2_VAL>=POWER(2,15),T20<POWER(2,15)))) -> 0 | AC20: BITWISE NOT OF REGA, RESULT STORED IN REGA
A21: 13 | B21: 19 | C21: ROL | D21: REG | E21: IMD | H21: REGA << IMD -> REGA | K21: 10 | L21: 3 | M21: 1 | N21: 0 | O21: 0 | P21: 0 | Q21: 0 | R21: 0 | S21: 0 | T21: =IF(CU_OPCODE=B21,_xlfn.BITLSHIFT(ALU_OPERAND1_VAL,ALU_OPERAND2_VAL), ALU_OUTPUT1) -> 0 | U21: =IF(CU_OPCODE=B21,MOD(T21,POWER(2,16)),ALU_OPERAND1_VAL) -> 0 | V21: =ALU_OPERAND2_VAL -> 0 | W21: =IF(CU_OPCODE=B21,INT(OR(T21<0,T21>POWER(2,16))),FLAGS_CF) -> 0 | X21: =IF(CU_OPCODE=B21,INT(U21=0),FLAGS_ZF) -> 0 | Y21: =INT(U21>=POWER(2,15)) -> 0 | Z21: =INT(OR(AND(ALU_OPERAND1_VAL<POWER(2,15),ALU_OPERAND2_VAL<POWER(2,15),U21>=POWER(2,15)),AND(ALU_OPERAND1_VAL>=POWER(2,15),ALU_OPERAND2_VAL>=POWER(2,15),T21<POWER(2,15)))) -> 0 | AC21: LEFTWISE ROLL OF BITS OF REGA CARRIED OUT 4b IMD TIMES
A22: 14 | B22: 20 | C22: ROR | D22: REG | E22: IMD | H22: REGA >> IMD -> REGA | K22: 11 | L22: 3 | M22: 1 | N22: 0 | O22: 0 | P22: 0 | Q22: 0 | R22: 0 | S22: 0 | T22: =IF(CU_OPCODE=B22, _xlfn.BITRSHIFT(ALU_OPERAND1_VAL,ALU_OPERAND2_VAL), ALU_OUTPUT1) -> 0 | U22: =IF(CU_OPCODE=B22,MOD(T22,POWER(2,16)),ALU_OPERAND1_VAL) -> 0 | V22: =ALU_OPERAND2_VAL -> 0 | W22: =IF(CU_OPCODE=B22,INT(OR(T22<0,T22>POWER(2,16))),FLAGS_CF) -> 0 | X22: =IF(CU_OPCODE=B22,INT(U22=0),FLAGS_ZF) -> 0 | Y22: =INT(U22>=POWER(2,15)) -> 0 | Z22: =INT(OR(AND(ALU_OPERAND1_VAL<POWER(2,15),ALU_OPERAND2_VAL<POWER(2,15),U22>=POWER(2,15)),AND(ALU_OPERAND1_VAL>=POWER(2,15),ALU_OPERAND2_VAL>=POWER(2,15),T22<POWER(2,15)))) -> 0 | AC22: RIGHTWISE ROLL OF BITS OF REGA CARRIED OUT 4b IMD TIMES
A23: 15 | B23: 21 | C23: CMP | D23: REG | E23: REG | H23: REGA - REGB -> ONLY FLAGS CHANGED | K23: 1 | L23: 1 | M23: 0 | N23: 0 | O23: 0 | P23: 0 | Q23: 0 | R23: 0 | S23: 0 | T23: 0 | U23: =IF(CU_OPCODE=B23,MOD(T23,POWER(2,16)),ALU_OPERAND1_VAL) -> 0 | V23: =ALU_OPERAND2_VAL -> 0 | W23: =IF(CU_OPCODE=B23,INT(OR(T23<0,T23>POWER(2,16))),FLAGS_CF) -> 0 | X23: =IF(CU_OPCODE=B23,INT(U23=0),FLAGS_ZF) -> 0 | Y23: =INT(U23>=POWER(2,15)) -> 0 | Z23: =INT(OR(AND(ALU_OPERAND1_VAL<POWER(2,15),ALU_OPERAND2_VAL<POWER(2,15),U23>=POWER(2,15)),AND(ALU_OPERAND1_VAL>=POWER(2,15),ALU_OPERAND2_VAL>=POWER(2,15),T23<POWER(2,15)))) -> 0 | AC23: SUBTRACTS REGA AND REGB, RESULTS NOT STORED, ONLY FLAGS AFFECTED
A24: 16 | B24: 22 | C24: CLC | H24: 0 -> C | K24: 13 | L24: 0 | M24: 0 | N24: 0 | O24: 0 | P24: 0 | Q24: 0 | R24: 0 | S24: 0 | T24: 0 | U24: =IF(CU_OPCODE=B24,MOD(T24,POWER(2,16)),ALU_OPERAND1_VAL) -> 0 | V24: =ALU_OPERAND2_VAL -> 0 | W24: =IF(CU_OPCODE=B24,INT(OR(T24<0,T24>POWER(2,16))),FLAGS_CF) -> 0 | X24: =IF(CU_OPCODE=B24,INT(U24=0),FLAGS_ZF) -> 0 | Y24: =INT(U24>=POWER(2,15)) -> 0 | Z24: =INT(OR(AND(ALU_OPERAND1_VAL<POWER(2,15),ALU_OPERAND2_VAL<POWER(2,15),U24>=POWER(2,15)),AND(ALU_OPERAND1_VAL>=POWER(2,15),ALU_OPERAND2_VAL>=POWER(2,15),T24<POWER(2,15)))) -> 0 | AC24: CARRY FLAG SET TO 0
A25: 17 | B25: 23 | C25: STC | H25: 1 -> C | K25: 14 | L25: 0 | M25: 0 | N25: 0 | O25: 0 | P25: 0 | Q25: 0 | R25: 0 | S25: 0 | T25: 0 | U25: =IF(CU_OPCODE=B25,MOD(T25,POWER(2,16)),ALU_OPERAND1_VAL) -> 0 | V25: =ALU_OPERAND2_VAL -> 0 | W25: =IF(CU_OPCODE=B25,INT(OR(T25<0,T25>POWER(2,16))),FLAGS_CF) -> 0 | X25: =IF(CU_OPCODE=B25,INT(U25=0),FLAGS_ZF) -> 0 | Y25: =INT(U25>=POWER(2,15)) -> 0 | Z25: =INT(OR(AND(ALU_OPERAND1_VAL<POWER(2,15),ALU_OPERAND2_VAL<POWER(2,15),U25>=POWER(2,15)),AND(ALU_OPERAND1_VAL>=POWER(2,15),ALU_OPERAND2_VAL>=POWER(2,15),T25<POWER(2,15)))) -> 0 | AC25: CARRY FLAG SET TO 1
A26: 18 | B26: 24 | C26: NOP | H26: NOTHING | K26: 15 | L26: 0 | M26: 0 | N26: 0 | O26: 0 | P26: 0 | Q26: 0 | R26: 0 | S26: 0 | T26: =ALU_OPERAND1_VAL -> 0 | U26: =ALU_OPERAND1_VAL -> 0 | V26: =ALU_OPERAND2_VAL -> 0 | W26: =FLAGS_CF -> 0 | X26: =FLAGS_ZF -> 0 | Y26: =FLAGS_SF -> 0 | Z26: =FLAGS_OF -> 0 | AC26: NO OPERATION IS DONE
A27: 19 | B27: 25 | C27: LOAD | D27: REG | E27: REG | H27: [REGB] -> REGA | K27: 15 | L27: 2 | M27: 1 | N27: 0 | O27: 0 | P27: 1 | Q27: 0 | R27: 0 | S27: 1 | T27: =IF(CU_OPCODE=B27,ALU_OPERAND2_VAL,T27) -> #N/A | U27: =ALU_OPERAND2_VAL -> 0 | V27: =ALU_OPERAND2_VAL -> 0 | W27: =FLAGS_CF -> 0 | X27: =FLAGS_ZF -> 0 | Y27: =FLAGS_SF -> 0 | Z27: =FLAGS_OF -> 0 | AA27: R | AC27: SETS REGA TO THE MEMORY VALUE OF THE ADDRESS IN REGB

Sheet ROM
A1: 1520 | B1: 53248 | C1: 1504 | D1: 1 | E1: 1280 | F1: 15 | G1: 2031 | H1: 3568 | I1: 3552 | J1: 3584 | K1: 256 | L1: 13 | M1: 0 | N1: 6 | O1: 5 | P1: 1072 | Q1: 3 | R1: 1088 | S1: 4 | T1: 1104 | U1: 6 | V1: 1488 | W1: 32 | X1: 0 | Y1: 27 | Z1: 0 | AA1: 47 | AB1: 2142 | AC1: 1838 | AD1: 5632 | AE1: 2541 | AF1: 1838 | AG1: 2541 | AH1: 1838 | AI1: 2541 | AJ1: 1838 | AK1: 0 | AL1: 25 | AM1: 2142 | AN1: 1806 | AO1: 5632 | AP1: 2541 | AQ1: 1806 | AR1: 2541 | AS1: 1806 | AT1: 2541 | AU1: 1806 | AV1: 2142 | AW1: 1472 | AX1: 4095 | AY1: 4076 | AZ1: 1472 | BA1: 128 | BB1: 3308 | BC1: 2251 | BD1: 0 | BE1: 90 | BF1: 5600 | BG1: 256 | BH1: 108 | BI1: 1472 | BJ1: 31 | BK1: 5612 | BL1: 256 | BM1: 108 | BN1: 1472 | BO1: 128 | BP1: 3052 | BQ1: 1472 | BR1: 61440 | BS1: 4332 | BT1: 2277 | BU1: 0 | BV1: 99 | BW1: 5552 | BX1: 256 | BY1: 113 | BZ1: 1472 | CA1: 31 | CB1: 5564 | CC1: 256 | CD1: 113 | CE1: 5632 | CF1: 2395 | CG1: 1472 | CH1: 4369 | CI1: 5632 | CJ1: 2348 | CK1: 0 | CL1: 23 | CM1: 5440 | CN1: 256 | CO1: 96 | CP1: 3552 | CQ1: 0 | CR1: 57 | CS1: 3808 | CT1: 0 | CU1: 57 | CV1: 5424 | CW1: 256 | CX1: 105 | CY1: 3504 | CZ1: 0 | DA1: 74 | DB1: 3760 | DC1: 0 | DD1: 74 | DE1: 1472 | DF1: 1 | DG1: 4428 | DH1: 0 | DI1: 65 | DJ1: 1472 | DK1: 1 | DL1: 4412 | DM1: 0 | DN1: 82 | DO1: 0 | DP1: 0 | DQ1: 0 | DR1: 0 | DS1: 0 | DT1: 0 | DU1: 0 | DV1: 0 | DW1: 0 | DX1: 0 | DY1: 0 | DZ1: 0 | EA1: 0 | EB1: 0 | EC1: 0 | ED1: 0 | EE1: 0 | EF1: 0 | EG1: 0 | EH1: 0 | EI1: 0 | EJ1: 0 | EK1: 0 | EL1: 0 | EM1: 0 | EN1: 0 | EO1: 0 | EP1: 0 | EQ1: 0 | ER1: 0 | ES1: 0 | ET1: 0 | EU1: 0 | EV1: 0 | EW1: 0 | EX1: 0 | EY1: 0 | EZ1: 0 | FA1: 0 | FB1: 0 | FC1: 0 | FD1: 0 | FE1: 0 | FF1: 0 | FG1: 0 | FH1: 0 | FI1: 0 | FJ1: 0 | FK1: 0 | FL1: 0 | FM1: 0 | FN1: 0 | FO1: 0 | FP1: 0 | FQ1: 0 | FR1: 0 | FS1: 0 | FT1: 0 | FU1: 0 | FV1: 0 | FW1: 0 | FX1: 0 | FY1: 0 | FZ1: 0 | GA1: 0 | GB1: 0 | GC1: 0 | GD1: 0 | GE1: 0 | GF1: 0 | GG1: 0 | GH1: 0 | GI1: 0 | GJ1: 0 | GK1: 0 | GL1: 0 | GM1: 0 | GN1: 0 | GO1: 0 | GP1: 0 | GQ1: 0 | GR1: 0 | GS1: 0 | GT1: 0 | GU1: 0 | GV1: 0 | GW1: 0 | GX1: 0 | GY1: 0 | GZ1: 0 | HA1: 0 | HB1: 0 | HC1: 0 | HD1: 0 | HE1: 0 | HF1: 0 | HG1: 0 | HH1: 0 | HI1: 0 | HJ1: 0 | HK1: 0 | HL1: 0 | HM1: 0 | HN1: 0 | HO1: 0 | HP1: 0 | HQ1: 0 | HR1: 0 | HS1: 0 | HT1: 0 | HU1: 0 | HV1: 0 | HW1: 0 | HX1: 0 | HY1: 0 | HZ1: 0 | IA1: 0 | IB1: 0 | IC1: 0 | ID1: 0 | IE1: 0 | IF1: 0 | IG1: 0 | IH1: 0 | II1: 0 | IJ1: 0 | IK1: 0 | IL1: 0 | IM1: 0 | IN1: 0 | IO1: 0 | IP1: 0 | IQ1: 0 | IR1: 0 | IS1: 0 | IT1: 0 | IU1: 0 | IV1: 0
A2: 0 | B2: 0 | C2: 0 | D2: 0 | E2: 0 | F2: 0 | G2: 0 | H2: 0 | I2: 0 | J2: 0 | K2: 0 | L2: 0 | M2: 0 | N2: 0 | O2: 0 | P2: 0 | Q2: 0 | R2: 0 | S2: 0 | T2: 0 | U2: 0 | V2: 0 | W2: 0 | X2: 0 | Y2: 0 | Z2: 0 | AA2: 0 | AB2: 0 | AC2: 0 | AD2: 0 | AE2: 0 | AF2: 0 | AG2: 0 | AH2: 0 | AI2: 0 | AJ2: 0 | AK2: 0 | AL2: 0 | AM2: 0 | AN2: 0 | AO2: 0 | AP2: 0 | AQ2: 0 | AR2: 0 | AS2: 0 | AT2: 0 | AU2: 0 | AV2: 0 | AW2: 0 | AX2: 0 | AY2: 0 | AZ2: 0 | BA2: 0 | BB2: 0 | BC2: 0 | BD2: 0 | BE2: 0 | BF2: 0 | BG2: 0 | BH2: 0 | BI2: 0 | BJ2: 0 | BK2: 0 | BL2: 0 | BM2: 0 | BN2: 0 | BO2: 0 | BP2: 0 | BQ2: 0 | BR2: 0 | BS2: 0 | BT2: 0 | BU2: 0 | BV2: 0 | BW2: 0 | BX2: 0 | BY2: 0 | BZ2: 0 | CA2: 0 | CB2: 0 | CC2: 0 | CD2: 0 | CE2: 0 | CF2: 0 | CG2: 0 | CH2: 0 | CI2: 0 | CJ2: 0 | CK2: 0 | CL2: 0 | CM2: 0 | CN2: 0 | CO2: 0 | CP2: 0 | CQ2: 0 | CR2: 0 | CS2: 0 | CT2: 0 | CU2: 0 | CV2: 0 | CW2: 0 | CX2: 0 | CY2: 0 | CZ2: 0 | DA2: 0 | DB2: 0 | DC2: 0 | DD2: 0 | DE2: 0 | DF2: 0 | DG2: 0 | DH2: 0 | DI2: 0 | DJ2: 0 | DK2: 0 | DL2: 0 | DM2: 0 | DN2: 0 | DO2: 0 | DP2: 0 | DQ2: 0 | DR2: 0 | DS2: 0 | DT2: 0 | DU2: 0 | DV2: 0 | DW2: 0 | DX2: 0 | DY2: 0 | DZ2: 0 | EA2: 0 | EB2: 0 | EC2: 0 | ED2: 0 | EE2: 0 | EF2: 0 | EG2: 0 | EH2: 0 | EI2: 0 | EJ2: 0 | EK2: 0 | EL2: 0 | EM2: 0 | EN2: 0 | EO2: 0 | EP2: 0 | EQ2: 0 | ER2: 0 | ES2: 0 | ET2: 0 | EU2: 0 | EV2: 0 | EW2: 0 | EX2: 0 | EY2: 0 | EZ2: 0 | FA2: 0 | FB2: 0 | FC2: 0 | FD2: 0 | FE2: 0 | FF2: 0 | FG2: 0 | FH2: 0 | FI2: 0 | FJ2: 0 | FK2: 0 | FL2: 0 | FM2: 0 | FN2: 0 | FO2: 0 | FP2: 0 | FQ2: 0 | FR2: 0 | FS2: 0 | FT2: 0 | FU2: 0 | FV2: 0 | FW2: 0 | FX2: 0 | FY2: 0 | FZ2: 0 | GA2: 0 | GB2: 0 | GC2: 0 | GD2: 0 | GE2: 0 | GF2: 0 | GG2: 0 | GH2: 0 | GI2: 0 | GJ2: 0 | GK2: 0 | GL2: 0 | GM2: 0 | GN2: 0 | GO2: 0 | GP2: 0 | GQ2: 0 | GR2: 0 | GS2: 0 | GT2: 0 | GU2: 0 | GV2: 0 | GW2: 0 | GX2: 0 | GY2: 0 | GZ2: 0 | HA2: 0 | HB2: 0 | HC2: 0 | HD2: 0 | HE2: 0 | HF2: 0 | HG2: 0 | HH2: 0 | HI2: 0 | HJ2: 0 | HK2: 0 | HL2: 0 | HM2: 0 | HN2: 0 | HO2: 0 | HP2: 0 | HQ2: 0 | HR2: 0 | HS2: 0 | HT2: 0 | HU2: 0 | HV2: 0 | HW2: 0 | HX2: 0 | HY2: 0 | HZ2: 0 | IA2: 0 | IB2: 0 | IC2: 0 | ID2: 0 | IE2: 0 | IF2: 0 | IG2: 0 | IH2: 0 | II2: 0 | IJ2: 0 | IK2: 0 | IL2: 0 | IM2: 0 | IN2: 0 | IO2: 0 | IP2: 0 | IQ2: 0 | IR2: 0 | IS2: 0 | IT2: 0 | IU2: 0 | IV2: 0
A3: 0 | B3: 0 | C3: 0 | D3: 0 | E3: 0 | F3: 0 | G3: 0 | H3: 0 | I3: 0 | J3: 0 | K3: 0 | L3: 0 | M3: 0 | N3: 0 | O3: 0 | P3: 0 | Q3: 0 | R3: 0 | S3: 0 | T3: 0 | U3: 0 | V3: 0 | W3: 0 | X3: 0 | Y3: 0 | Z3: 0 | AA3: 0 | AB3: 0 | AC3: 0 | AD3: 0 | AE3: 0 | AF3: 0 | AG3: 0 | AH3: 0 | AI3: 0 | AJ3: 0 | AK3: 0 | AL3: 0 | AM3: 0 | AN3: 0 | AO3: 0 | AP3: 0 | AQ3: 0 | AR3: 0 | AS3: 0 | AT3: 0 | AU3: 0 | AV3: 0 | AW3: 0 | AX3: 0 | AY3: 0 | AZ3: 0 | BA3: 0 | BB3: 0 | BC3: 0 | BD3: 0 | BE3: 0 | BF3: 0 | BG3: 0 | BH3: 0 | BI3: 0 | BJ3: 0 | BK3: 0 | BL3: 0 | BM3: 0 | BN3: 0 | BO3: 0 | BP3: 0 | BQ3: 0 | BR3: 0 | BS3: 0 | BT3: 0 | BU3: 0 | BV3: 0 | BW3: 0 | BX3: 0 | BY3: 0 | BZ3: 0 | CA3: 0 | CB3: 0 | CC3: 0 | CD3: 0 | CE3: 0 | CF3: 0 | CG3: 0 | CH3: 0 | CI3: 0 | CJ3: 0 | CK3: 0 | CL3: 0 | CM3: 0 | CN3: 0 | CO3: 0 | CP3: 0 | CQ3: 0 | CR3: 0 | CS3: 0 | CT3: 0 | CU3: 0 | CV3: 0 | CW3: 0 | CX3: 0 | CY3: 0 | CZ3: 0 | DA3: 0 | DB3: 0 | DC3: 0 | DD3: 0 | DE3: 0 | DF3: 0 | DG3: 0 | DH3: 0 | DI3: 0 | DJ3: 0 | DK3: 0 | DL3: 0 | DM3: 0 | DN3: 0 | DO3: 0 | DP3: 0 | DQ3: 0 | DR3: 0 | DS3: 0 | DT3: 0 | DU3: 0 | DV3: 0 | DW3: 0 | DX3: 0 | DY3: 0 | DZ3: 0 | EA3: 0 | EB3: 0 | EC3: 0 | ED3: 0 | EE3: 0 | EF3: 0 | EG3: 0 | EH3: 0 | EI3: 0 | EJ3: 0 | EK3: 0 | EL3: 0 | EM3: 0 | EN3: 0 | EO3: 0 | EP3: 0 | EQ3: 0 | ER3: 0 | ES3: 0 | ET3: 0 | EU3: 0 | EV3: 0 | EW3: 0 | EX3: 0 | EY3: 0 | EZ3: 0 | FA3: 0 | FB3: 0 | FC3: 0 | FD3: 0 | FE3: 0 | FF3: 0 | FG3: 0 | FH3: 0 | FI3: 0 | FJ3: 0 | FK3: 0 | FL3: 0 | FM3: 0 | FN3: 0 | FO3: 0 | FP3: 0 | FQ3: 0 | FR3: 0 | FS3: 0 | FT3: 0 | FU3: 0 | FV3: 0 | FW3: 0 | FX3: 0 | FY3: 0 | FZ3: 0 | GA3: 0 | GB3: 0 | GC3: 0 | GD3: 0 | GE3: 0 | GF3: 0 | GG3: 0 | GH3: 0 | GI3: 0 | GJ3: 0 | GK3: 0 | GL3: 0 | GM3: 0 | GN3: 0 | GO3: 0 | GP3: 0 | GQ3: 0 | GR3: 0 | GS3: 0 | GT3: 0 | GU3: 0 | GV3: 0 | GW3: 0 | GX3: 0 | GY3: 0 | GZ3: 0 | HA3: 0 | HB3: 0 | HC3: 0 | HD3: 0 | HE3: 0 | HF3: 0 | HG3: 0 | HH3: 0 | HI3: 0 | HJ3: 0 | HK3: 0 | HL3: 0 | HM3: 0 | HN3: 0 | HO3: 0 | HP3: 0 | HQ3: 0 | HR3: 0 | HS3: 0 | HT3: 0 | HU3: 0 | HV3: 0 | HW3: 0 | HX3: 0 | HY3: 0 | HZ3: 0 | IA3: 0 | IB3: 0 | IC3: 0 | ID3: 0 | IE3: 0 | IF3: 0 | IG3: 0 | IH3: 0 | II3: 0 | IJ3: 0 | IK3: 0 | IL3: 0 | IM3: 0 | IN3: 0 | IO3: 0 | IP3: 0 | IQ3: 0 | IR3: 0 | IS3: 0 | IT3: 0 | IU3: 0 | IV3: 0
A4: 0 | B4: 0 | C4: 0 | D4: 0 | E4: 0 | F4: 0 | G4: 0 | H4: 0 | I4: 0 | J4: 0 | K4: 0 | L4: 0 | M4: 0 | N4: 0 | O4: 0 | P4: 0 | Q4: 0 | R4: 0 | S4: 0 | T4: 0 | U4: 0 | V4: 0 | W4: 0 | X4: 0 | Y4: 0 | Z4: 0 | AA4: 0 | AB4: 0 | AC4: 0 | AD4: 0 | AE4: 0 | AF4: 0 | AG4: 0 | AH4: 0 | AI4: 0 | AJ4: 0 | AK4: 0 | AL4: 0 | AM4: 0 | AN4: 0 | AO4: 0 | AP4: 0 | AQ4: 0 | AR4: 0 | AS4: 0 | AT4: 0 | AU4: 0 | AV4: 0 | AW4: 0 | AX4: 0 | AY4: 0 | AZ4: 0 | BA4: 0 | BB4: 0 | BC4: 0 | BD4: 0 | BE4: 0 | BF4: 0 | BG4: 0 | BH4: 0 | BI4: 0 | BJ4: 0 | BK4: 0 | BL4: 0 | BM4: 0 | BN4: 0 | BO4: 0 | BP4: 0 | BQ4: 0 | BR4: 0 | BS4: 0 | BT4: 0 | BU4: 0 | BV4: 0 | BW4: 0 | BX4: 0 | BY4: 0 | BZ4: 0 | CA4: 0 | CB4: 0 | CC4: 0 | CD4: 0 | CE4: 0 | CF4: 0 | CG4: 0 | CH4: 0 | CI4: 0 | CJ4: 0 | CK4: 0 | CL4: 0 | CM4: 0 | CN4: 0 | CO4: 0 | CP4: 0 | CQ4: 0 | CR4: 0 | CS4: 0 | CT4: 0 | CU4: 0 | CV4: 0 | CW4: 0 | CX4: 0 | CY4: 0 | CZ4: 0 | DA4: 0 | DB4: 0 | DC4: 0 | DD4: 0 | DE4: 0 | DF4: 0 | DG4: 0 | DH4: 0 | DI4: 0 | DJ4: 0 | DK4: 0 | DL4: 0 | DM4: 0 | DN4: 0 | DO4: 0 | DP4: 0 | DQ4: 0 | DR4: 0 | DS4: 0 | DT4: 0 | DU4: 0 | DV4: 0 | DW4: 0 | DX4: 0 | DY4: 0 | DZ4: 0 | EA4: 0 | EB4: 0 | EC4: 0 | ED4: 0 | EE4: 0 | EF4: 0 | EG4: 0 | EH4: 0 | EI4: 0 | EJ4: 0 | EK4: 0 | EL4: 0 | EM4: 0 | EN4: 0 | EO4: 0 | EP4: 0 | EQ4: 0 | ER4: 0 | ES4: 0 | ET4: 0 | EU4: 0 | EV4: 0 | EW4: 0 | EX4: 0 | EY4: 0 | EZ4: 0 | FA4: 0 | FB4: 0 | FC4: 0 | FD4: 0 | FE4: 0 | FF4: 0 | FG4: 0 | FH4: 0 | FI4: 0 | FJ4: 0 | FK4: 0 | FL4: 0 | FM4: 0 | FN4: 0 | FO4: 0 | FP4: 0 | FQ4: 0 | FR4: 0 | FS4: 0 | FT4: 0 | FU4: 0 | FV4: 0 | FW4: 0 | FX4: 0 | FY4: 0 | FZ4: 0 | GA4: 0 | GB4: 0 | GC4: 0 | GD4: 0 | GE4: 0 | GF4: 0 | GG4: 0 | GH4: 0 | GI4: 0 | GJ4: 0 | GK4: 0 | GL4: 0 | GM4: 0 | GN4: 0 | GO4: 0 | GP4: 0 | GQ4: 0 | GR4: 0 | GS4: 0 | GT4: 0 | GU4: 0 | GV4: 0 | GW4: 0 | GX4: 0 | GY4: 0 | GZ4: 0 | HA4: 0 | HB4: 0 | HC4: 0 | HD4: 0 | HE4: 0 | HF4: 0 | HG4: 0 | HH4: 0 | HI4: 0 | HJ4: 0 | HK4: 0 | HL4: 0 | HM4: 0 | HN4: 0 | HO4: 0 | HP4: 0 | HQ4: 0 | HR4: 0 | HS4: 0 | HT4: 0 | HU4: 0 | HV4: 0 | HW4: 0 | HX4: 0 | HY4: 0 | HZ4: 0 | IA4: 0 | IB4: 0 | IC4: 0 | ID4: 0 | IE4: 0 | IF4: 0 | IG4: 0 | IH4: 0 | II4: 0 | IJ4: 0 | IK4: 0 | IL4: 0 | IM4: 0 | IN4: 0 | IO4: 0 | IP4: 0 | IQ4: 0 | IR4: 0 | IS4: 0 | IT4: 0 | IU4: 0 | IV4: 0
A5: 0 | B5: 0 | C5: 0 | D5: 0 | E5: 0 | F5: 0 | G5: 0 | H5: 0 | I5: 0 | J5: 0 | K5: 0 | L5: 0 | M5: 0 | N5: 0 | O5: 0 | P5: 0 | Q5: 0 | R5: 0 | S5: 0 | T5: 0 | U5: 0 | V5: 0 | W5: 0 | X5: 0 | Y5: 0 | Z5: 0 | AA5: 0 | AB5: 0 | AC5: 0 | AD5: 0 | AE5: 0 | AF5: 0 | AG5: 0 | AH5: 0 | AI5: 0 | AJ5: 0 | AK5: 0 | AL5: 0 | AM5: 0 | AN5: 0 | AO5: 0 | AP5: 0 | AQ5: 0 | AR5: 0 | AS5: 0 | AT5: 0 | AU5: 0 | AV5: 0 | AW5: 0 | AX5: 0 | AY5: 0 | AZ5: 0 | BA5: 0 | BB5: 0 | BC5: 0 | BD5: 0 | BE5: 0 | BF5: 0 | BG5: 0 | BH5: 0 | BI5: 0 | BJ5: 0 | BK5: 0 | BL5: 0 | BM5: 0 | BN5: 0 | BO5: 0 | BP5: 0 | BQ5: 0 | BR5: 0 | BS5: 0 | BT5: 0 | BU5: 0 | BV5: 0 | BW5: 0 | BX5: 0 | BY5: 0 | BZ5: 0 | CA5: 0 | CB5: 0 | CC5: 0 | CD5: 0 | CE5: 0 | CF5: 0 | CG5: 0 | CH5: 0 | CI5: 0 | CJ5: 0 | CK5: 0 | CL5: 0 | CM5: 0 | CN5: 0 | CO5: 0 | CP5: 0 | CQ5: 0 | CR5: 0 | CS5: 0 | CT5: 0 | CU5: 0 | CV5: 0 | CW5: 0 | CX5: 0 | CY5: 0 | CZ5: 0 | DA5: 0 | DB5: 0 | DC5: 0 | DD5: 0 | DE5: 0 | DF5: 0 | DG5: 0 | DH5: 0 | DI5: 0 | DJ5: 0 | DK5: 0 | DL5: 0 | DM5: 0 | DN5: 0 | DO5: 0 | DP5: 0 | DQ5: 0 | DR5: 0 | DS5: 0 | DT5: 0 | DU5: 0 | DV5: 0 | DW5: 0 | DX5: 0 | DY5: 0 | DZ5: 0 | EA5: 0 | EB5: 0 | EC5: 0 | ED5: 0 | EE5: 0 | EF5: 0 | EG5: 0 | EH5: 0 | EI5: 0 | EJ5: 0 | EK5: 0 | EL5: 0 | EM5: 0 | EN5: 0 | EO5: 0 | EP5: 0 | EQ5: 0 | ER5: 0 | ES5: 0 | ET5: 0 | EU5: 0 | EV5: 0 | EW5: 0 | EX5: 0 | EY5: 0 | EZ5: 0 | FA5: 0 | FB5: 0 | FC5: 0 | FD5: 0 | FE5: 0 | FF5: 0 | FG5: 0 | FH5: 0 | FI5: 0 | FJ5: 0 | FK5: 0 | FL5: 0 | FM5: 0 | FN5: 0 | FO5: 0 | FP5: 0 | FQ5: 0 | FR5: 0 | FS5: 0 | FT5: 0 | FU5: 0 | FV5: 0 | FW5: 0 | FX5: 0 | FY5: 0 | FZ5: 0 | GA5: 0 | GB5: 0 | GC5: 0 | GD5: 0 | GE5: 0 | GF5: 0 | GG5: 0 | GH5: 0 | GI5: 0 | GJ5: 0 | GK5: 0 | GL5: 0 | GM5: 0 | GN5: 0 | GO5: 0 | GP5: 0 | GQ5: 0 | GR5: 0 | GS5: 0 | GT5: 0 | GU5: 0 | GV5: 0 | GW5: 0 | GX5: 0 | GY5: 0 | GZ5: 0 | HA5: 0 | HB5: 0 | HC5: 0 | HD5: 0 | HE5: 0 | HF5: 0 | HG5: 0 | HH5: 0 | HI5: 0 | HJ5: 0 | HK5: 0 | HL5: 0 | HM5: 0 | HN5: 0 | HO5: 0 | HP5: 0 | HQ5: 0 | HR5: 0 | HS5: 0 | HT5: 0 | HU5: 0 | HV5: 0 | HW5: 0 | HX5: 0 | HY5: 0 | HZ5: 0 | IA5: 0 | IB5: 0 | IC5: 0 | ID5: 0 | IE5: 0 | IF5: 0 | IG5: 0 | IH5: 0 | II5: 0 | IJ5: 0 | IK5: 0 | IL5: 0 | IM5: 0 | IN5: 0 | IO5: 0 | IP5: 0 | IQ5: 0 | IR5: 0 | IS5: 0 | IT5: 0 | IU5: 0 | IV5: 0
A6: 0 | B6: 0 | C6: 0 | D6: 0 | E6: 0 | F6: 0 | G6: 0 | H6: 0 | I6: 0 | J6: 0 | K6: 0 | L6: 0 | M6: 0 | N6: 0 | O6: 0 | P6: 0 | Q6: 0 | R6: 0 | S6: 0 | T6: 0 | U6: 0 | V6: 0 | W6: 0 | X6: 0 | Y6: 0 | Z6: 0 | AA6: 0 | AB6: 0 | AC6: 0 | AD6: 0 | AE6: 0 | AF6: 0 | AG6: 0 | AH6: 0 | AI6: 0 | AJ6: 0 | AK6: 0 | AL6: 0 | AM6: 0 | AN6: 0 | AO6: 0 | AP6: 0 | AQ6: 0 | AR6: 0 | AS6: 0 | AT6: 0 | AU6: 0 | AV6: 0 | AW6: 0 | AX6: 0 | AY6: 0 | AZ6: 0 | BA6: 0 | BB6: 0 | BC6: 0 | BD6: 0 | BE6: 0 | BF6: 0 | BG6: 0 | BH6: 0 | BI6: 0 | BJ6: 0 | BK6: 0 | BL6: 0 | BM6: 0 | BN6: 0 | BO6: 0 | BP6: 0 | BQ6: 0 | BR6: 0 | BS6: 0 | BT6: 0 | BU6: 0 | BV6: 0 | BW6: 0 | BX6: 0 | BY6: 0 | BZ6: 0 | CA6: 0 | CB6: 0 | CC6: 0 | CD6: 0 | CE6: 0 | CF6: 0 | CG6: 0 | CH6: 0 | CI6: 0 | CJ6: 0 | CK6: 0 | CL6: 0 | CM6: 0 | CN6: 0 | CO6: 0 | CP6: 0 | CQ6: 0 | CR6: 0 | CS6: 0 | CT6: 0 | CU6: 0 | CV6: 0 | CW6: 0 | CX6: 0 | CY6: 0 | CZ6: 0 | DA6: 0 | DB6: 0 | DC6: 0 | DD6: 0 | DE6: 0 | DF6: 0 | DG6: 0 | DH6: 0 | DI6: 0 | DJ6: 0 | DK6: 0 | DL6: 0 | DM6: 0 | DN6: 0 | DO6: 0 | DP6: 0 | DQ6: 0 | DR6: 0 | DS6: 0 | DT6: 0 | DU6: 0 | DV6: 0 | DW6: 0 | DX6: 0 | DY6: 0 | DZ6: 0 | EA6: 0 | EB6: 0 | EC6: 0 | ED6: 0 | EE6: 0 | EF6: 0 | EG6: 0 | EH6: 0 | EI6: 0 | EJ6: 0 | EK6: 0 | EL6: 0 | EM6: 0 | EN6: 0 | EO6: 0 | EP6: 0 | EQ6: 0 | ER6: 0 | ES6: 0 | ET6: 0 | EU6: 0 | EV6: 0 | EW6: 0 | EX6: 0 | EY6: 0 | EZ6: 0 | FA6: 0 | FB6: 0 | FC6: 0 | FD6: 0 | FE6: 0 | FF6: 0 | FG6: 0 | FH6: 0 | FI6: 0 | FJ6: 0 | FK6: 0 | FL6: 0 | FM6: 0 | FN6: 0 | FO6: 0 | FP6: 0 | FQ6: 0 | FR6: 0 | FS6: 0 | FT6: 0 | FU6: 0 | FV6: 0 | FW6: 0 | FX6: 0 | FY6: 0 | FZ6: 0 | GA6: 0 | GB6: 0 | GC6: 0 | GD6: 0 | GE6: 0 | GF6: 0 | GG6: 0 | GH6: 0 | GI6: 0 | GJ6: 0 | GK6: 0 | GL6: 0 | GM6: 0 | GN6: 0 | GO6: 0 | GP6: 0 | GQ6: 0 | GR6: 0 | GS6: 0 | GT6: 0 | GU6: 0 | GV6: 0 | GW6: 0 | GX6: 0 | GY6: 0 | GZ6: 0 | HA6: 0 | HB6: 0 | HC6: 0 | HD6: 0 | HE6: 0 | HF6: 0 | HG6: 0 | HH6: 0 | HI6: 0 | HJ6: 0 | HK6: 0 | HL6: 0 | HM6: 0 | HN6: 0 | HO6: 0 | HP6: 0 | HQ6: 0 | HR6: 0 | HS6: 0 | HT6: 0 | HU6: 0 | HV6: 0 | HW6: 0 | HX6: 0 | HY6: 0 | HZ6: 0 | IA6: 0 | IB6: 0 | IC6: 0 | ID6: 0 | IE6: 0 | IF6: 0 | IG6: 0 | IH6: 0 | II6: 0 | IJ6: 0 | IK6: 0 | IL6: 0 | IM6: 0 | IN6: 0 | IO6: 0 | IP6: 0 | IQ6: 0 | IR6: 0 | IS6: 0 | IT6: 0 | IU6: 0 | IV6: 0
A7: 0 | B7: 0 | C7: 0 | D7: 0 | E7: 0 | F7: 0 | G7: 0 | H7: 0 | I7: 0 | J7: 0 | K7: 0 | L7: 0 | M7: 0 | N7: 0 | O7: 0 | P7: 0 | Q7: 0 | R7: 0 | S7: 0 | T7: 0 | U7: 0 | V7: 0 | W7: 0 | X7: 0 | Y7: 0 | Z7: 0 | AA7: 0 | AB7: 0 | AC7: 0 | AD7: 0 | AE7: 0 | AF7: 0 | AG7: 0 | AH7: 0 | AI7: 0 | AJ7: 0 | AK7: 0 | AL7: 0 | AM7: 0 | AN7: 0 | AO7: 0 | AP7: 0 | AQ7: 0 | AR7: 0 | AS7: 0 | AT7: 0 | AU7: 0 | AV7: 0 | AW7: 0 | AX7: 0 | AY7: 0 | AZ7: 0 | BA7: 0 | BB7: 0 | BC7: 0 | BD7: 0 | BE7: 0 | BF7: 0 | BG7: 0 | BH7: 0 | BI7: 0 | BJ7: 0 | BK7: 0 | BL7: 0 | BM7: 0 | BN7: 0 | BO7: 0 | BP7: 0 | BQ7: 0 | BR7: 0 | BS7: 0 | BT7: 0 | BU7: 0 | BV7: 0 | BW7: 0 | BX7: 0 | BY7: 0 | BZ7: 0 | CA7: 0 | CB7: 0 | CC7: 0 | CD7: 0 | CE7: 0 | CF7: 0 | CG7: 0 | CH7: 0 | CI7: 0 | CJ7: 0 | CK7: 0 | CL7: 0 | CM7: 0 | CN7: 0 | CO7: 0 | CP7: 0 | CQ7: 0 | CR7: 0 | CS7: 0 | CT7: 0 | CU7: 0 | CV7: 0 | CW7: 0 | CX7: 0 | CY7: 0 | CZ7: 0 | DA7: 0 | DB7: 0 | DC7: 0 | DD7: 0 | DE7: 0 | DF7: 0 | DG7: 0 | DH7: 0 | DI7: 0 | DJ7: 0 | DK7: 0 | DL7: 0 | DM7: 0 | DN7: 0 | DO7: 0 | DP7: 0 | DQ7: 0 | DR7: 0 | DS7: 0 | DT7: 0 | DU7: 0 | DV7: 0 | DW7: 0 | DX7: 0 | DY7: 0 | DZ7: 0 | EA7: 0 | EB7: 0 | EC7: 0 | ED7: 0 | EE7: 0 | EF7: 0 | EG7: 0 | EH7: 0 | EI7: 0 | EJ7: 0 | EK7: 0 | EL7: 0 | EM7: 0 | EN7: 0 | EO7: 0 | EP7: 0 | EQ7: 0 | ER7: 0 | ES7: 0 | ET7: 0 | EU7: 0 | EV7: 0 | EW7: 0 | EX7: 0 | EY7: 0 | EZ7: 0 | FA7: 0 | FB7: 0 | FC7: 0 | FD7: 0 | FE7: 0 | FF7: 0 | FG7: 0 | FH7: 0 | FI7: 0 | FJ7: 0 | FK7: 0 | FL7: 0 | FM7: 0 | FN7: 0 | FO7: 0 | FP7: 0 | FQ7: 0 | FR7: 0 | FS7: 0 | FT7: 0 | FU7: 0 | FV7: 0 | FW7: 0 | FX7: 0 | FY7: 0 | FZ7: 0 | GA7: 0 | GB7: 0 | GC7: 0 | GD7: 0 | GE7: 0 | GF7: 0 | GG7: 0 | GH7: 0 | GI7: 0 | GJ7: 0 | GK7: 0 | GL7: 0 | GM7: 0 | GN7: 0 | GO7: 0 | GP7: 0 | GQ7: 0 | GR7: 0 | GS7: 0 | GT7: 0 | GU7: 0 | GV7: 0 | GW7: 0 | GX7: 0 | GY7: 0 | GZ7: 0 | HA7: 0 | HB7: 0 | HC7: 0 | HD7: 0 | HE7: 0 | HF7: 0 | HG7: 0 | HH7: 0 | HI7: 0 | HJ7: 0 | HK7: 0 | HL7: 0 | HM7: 0 | HN7: 0 | HO7: 0 | HP7: 0 | HQ7: 0 | HR7: 0 | HS7: 0 | HT7: 0 | HU7: 0 | HV7: 0 | HW7: 0 | HX7: 0 | HY7: 0 | HZ7: 0 | IA7: 0 | IB7: 0 | IC7: 0 | ID7: 0 | IE7: 0 | IF7: 0 | IG7: 0 | IH7: 0 | II7: 0 | IJ7: 0 | IK7: 0 | IL7: 0 | IM7: 0 | IN7: 0 | IO7: 0 | IP7: 0 | IQ7: 0 | IR7: 0 | IS7: 0 | IT7: 0 | IU7: 0 | IV7: 0
A8: 0 | B8: 0 | C8: 0 | D8: 0 | E8: 0 | F8: 0 | G8: 0 | H8: 0 | I8: 0 | J8: 0 | K8: 0 | L8: 0 | M8: 0 | N8: 0 | O8: 0 | P8: 0 | Q8: 0 | R8: 0 | S8: 0 | T8: 0 | U8: 0 | V8: 0 | W8: 0 | X8: 0 | Y8: 0 | Z8: 0 | AA8: 0 | AB8: 0 | AC8: 0 | AD8: 0 | AE8: 0 | AF8: 0 | AG8: 0 | AH8: 0 | AI8: 0 | AJ8: 0 | AK8: 0 | AL8: 0 | AM8: 0 | AN8: 0 | AO8: 0 | AP8: 0 | AQ8: 0 | AR8: 0 | AS8: 0 | AT8: 0 | AU8: 0 | AV8: 0 | AW8: 0 | AX8: 0 | AY8: 0 | AZ8: 0 | BA8: 0 | BB8: 0 | BC8: 0 | BD8: 0 | BE8: 0 | BF8: 0 | BG8: 0 | BH8: 0 | BI8: 0 | BJ8: 0 | BK8: 0 | BL8: 0 | BM8: 0 | BN8: 0 | BO8: 0 | BP8: 0 | BQ8: 0 | BR8: 0 | BS8: 0 | BT8: 0 | BU8: 0 | BV8: 0 | BW8: 0 | BX8: 0 | BY8: 0 | BZ8: 0 | CA8: 0 | CB8: 0 | CC8: 0 | CD8: 0 | CE8: 0 | CF8: 0 | CG8: 0 | CH8: 0 | CI8: 0 | CJ8: 0 | CK8: 0 | CL8: 0 | CM8: 0 | CN8: 0 | CO8: 0 | CP8: 0 | CQ8: 0 | CR8: 0 | CS8: 0 | CT8: 0 | CU8: 0 | CV8: 0 | CW8: 0 | CX8: 0 | CY8: 0 | CZ8: 0 | DA8: 0 | DB8: 0 | DC8: 0 | DD8: 0 | DE8: 0 | DF8: 0 | DG8: 0 | DH8: 0 | DI8: 0 | DJ8: 0 | DK8: 0 | DL8: 0 | DM8: 0 | DN8: 0 | DO8: 0 | DP8: 0 | DQ8: 0 | DR8: 0 | DS8: 0 | DT8: 0 | DU8: 0 | DV8: 0 | DW8: 0 | DX8: 0 | DY8: 0 | DZ8: 0 | EA8: 0 | EB8: 0 | EC8: 0 | ED8: 0 | EE8: 0 | EF8: 0 | EG8: 0 | EH8: 0 | EI8: 0 | EJ8: 0 | EK8: 0 | EL8: 0 | EM8: 0 | EN8: 0 | EO8: 0 | EP8: 0 | EQ8: 0 | ER8: 0 | ES8: 0 | ET8: 0 | EU8: 0 | EV8: 0 | EW8: 0 | EX8: 0 | EY8: 0 | EZ8: 0 | FA8: 0 | FB8: 0 | FC8: 0 | FD8: 0 | FE8: 0 | FF8: 0 | FG8: 0 | FH8: 0 | FI8: 0 | FJ8: 0 | FK8: 0 | FL8: 0 | FM8: 0 | FN8: 0 | FO8: 0 | FP8: 0 | FQ8: 0 | FR8: 0 | FS8: 0 | FT8: 0 | FU8: 0 | FV8: 0 | FW8: 0 | FX8: 0 | FY8: 0 | FZ8: 0 | GA8: 0 | GB8: 0 | GC8: 0 | GD8: 0 | GE8: 0 | GF8: 0 | GG8: 0 | GH8: 0 | GI8: 0 | GJ8: 0 | GK8: 0 | GL8: 0 | GM8: 0 | GN8: 0 | GO8: 0 | GP8: 0 | GQ8: 0 | GR8: 0 | GS8: 0 | GT8: 0 | GU8: 0 | GV8: 0 | GW8: 0 | GX8: 0 | GY8: 0 | GZ8: 0 | HA8: 0 | HB8: 0 | HC8: 0 | HD8: 0 | HE8: 0 | HF8: 0 | HG8: 0 | HH8: 0 | HI8: 0 | HJ8: 0 | HK8: 0 | HL8: 0 | HM8: 0 | HN8: 0 | HO8: 0 | HP8: 0 | HQ8: 0 | HR8: 0 | HS8: 0 | HT8: 0 | HU8: 0 | HV8: 0 | HW8: 0 | HX8: 0 | HY8: 0 | HZ8: 0 | IA8: 0 | IB8: 0 | IC8: 0 | ID8: 0 | IE8: 0 | IF8: 0 | IG8: 0 | IH8: 0 | II8: 0 | IJ8: 0 | IK8: 0 | IL8: 0 | IM8: 0 | IN8: 0 | IO8: 0 | IP8: 0 | IQ8: 0 | IR8: 0 | IS8: 0 | IT8: 0 | IU8: 0 | IV8: 0
A9: 0 | B9: 0 | C9: 0 | D9: 0 | E9: 0 | F9: 0 | G9: 0 | H9: 0 | I9: 0 | J9: 0 | K9: 0 | L9: 0 | M9: 0 | N9: 0 | O9: 0 | P9: 0 | Q9: 0 | R9: 0 | S9: 0 | T9: 0 | U9: 0 | V9: 0 | W9: 0 | X9: 0 | Y9: 0 | Z9: 0 | AA9: 0 | AB9: 0 | AC9: 0 | AD9: 0 | AE9: 0 | AF9: 0 | AG9: 0 | AH9: 0 | AI9: 0 | AJ9: 0 | AK9: 0 | AL9: 0 | AM9: 0 | AN9: 0 | AO9: 0 | AP9: 0 | AQ9: 0 | AR9: 0 | AS9: 0 | AT9: 0 | AU9: 0 | AV9: 0 | AW9: 0 | AX9: 0 | AY9: 0 | AZ9: 0 | BA9: 0 | BB9: 0 | BC9: 0 | BD9: 0 | BE9: 0 | BF9: 0 | BG9: 0 | BH9: 0 | BI9: 0 | BJ9: 0 | BK9: 0 | BL9: 0 | BM9: 0 | BN9: 0 | BO9: 0 | BP9: 0 | BQ9: 0 | BR9: 0 | BS9: 0 | BT9: 0 | BU9: 0 | BV9: 0 | BW9: 0 | BX9: 0 | BY9: 0 | BZ9: 0 | CA9: 0 | CB9: 0 | CC9: 0 | CD9: 0 | CE9: 0 | CF9: 0 | CG9: 0 | CH9: 0 | CI9: 0 | CJ9: 0 | CK9: 0 | CL9: 0 | CM9: 0 | CN9: 0 | CO9: 0 | CP9: 0 | CQ9: 0 | CR9: 0 | CS9: 0 | CT9: 0 | CU9: 0 | CV9: 0 | CW9: 0 | CX9: 0 | CY9: 0 | CZ9: 0 | DA9: 0 | DB9: 0 | DC9: 0 | DD9: 0 | DE9: 0 | DF9: 0 | DG9: 0 | DH9: 0 | DI9: 0 | DJ9: 0 | DK9: 0 | DL9: 0 | DM9: 0 | DN9: 0 | DO9: 0 | DP9: 0 | DQ9: 0 | DR9: 0 | DS9: 0 | DT9: 0 | DU9: 0 | DV9: 0 | DW9: 0 | DX9: 0 | DY9: 0 | DZ9: 0 | EA9: 0 | EB9: 0 | EC9: 0 | ED9: 0 | EE9: 0 | EF9: 0 | EG9: 0 | EH9: 0 | EI9: 0 | EJ9: 0 | EK9: 0 | EL9: 0 | EM9: 0 | EN9: 0 | EO9: 0 | EP9: 0 | EQ9: 0 | ER9: 0 | ES9: 0 | ET9: 0 | EU9: 0 | EV9: 0 | EW9: 0 | EX9: 0 | EY9: 0 | EZ9: 0 | FA9: 0 | FB9: 0 | FC9: 0 | FD9: 0 | FE9: 0 | FF9: 0 | FG9: 0 | FH9: 0 | FI9: 0 | FJ9: 0 | FK9: 0 | FL9: 0 | FM9: 0 | FN9: 0 | FO9: 0 | FP9: 0 | FQ9: 0 | FR9: 0 | FS9: 0 | FT9: 0 | FU9: 0 | FV9: 0 | FW9: 0 | FX9: 0 | FY9: 0 | FZ9: 0 | GA9: 0 | GB9: 0 | GC9: 0 | GD9: 0 | GE9: 0 | GF9: 0 | GG9: 0 | GH9: 0 | GI9: 0 | GJ9: 0 | GK9: 0 | GL9: 0 | GM9: 0 | GN9: 0 | GO9: 0 | GP9: 0 | GQ9: 0 | GR9: 0 | GS9: 0 | GT9: 0 | GU9: 0 | GV9: 0 | GW9: 0 | GX9: 0 | GY9: 0 | GZ9: 0 | HA9: 0 | HB9: 0 | HC9: 0 | HD9: 0 | HE9: 0 | HF9: 0 | HG9: 0 | HH9: 0 | HI9: 0 | HJ9: 0 | HK9: 0 | HL9: 0 | HM9: 0 | HN9: 0 | HO9: 0 | HP9: 0 | HQ9: 0 | HR9: 0 | HS9: 0 | HT9: 0 | HU9: 0 | HV9: 0 | HW9: 0 | HX9: 0 | HY9: 0 | HZ9: 0 | IA9: 0 | IB9: 0 | IC9: 0 | ID9: 0 | IE9: 0 | IF9: 0 | IG9: 0 | IH9: 0 | II9: 0 | IJ9: 0 | IK9: 0 | IL9: 0 | IM9: 0 | IN9: 0 | IO9: 0 | IP9: 0 | IQ9: 0 | IR9: 0 | IS9: 0 | IT9: 0 | IU9: 0 | IV9: 0
A10: 0 | B10: 0 | C10: 0 | D10: 0 | E10: 0 | F10: 0 | G10: 0 | H10: 0 | I10: 0 | J10: 0 | K10: 0 | L10: 0 | M10: 0 | N10: 0 | O10: 0 | P10: 0 | Q10: 0 | R10: 0 | S10: 0 | T10: 0 | U10: 0 | V10: 0 | W10: 0 | X10: 0 | Y10: 0 | Z10: 0 | AA10: 0 | AB10: 0 | AC10: 0 | AD10: 0 | AE10: 0 | AF10: 0 | AG10: 0 | AH10: 0 | AI10: 0 | AJ10: 0 | AK10: 0 | AL10: 0 | AM10: 0 | AN10: 0 | AO10: 0 | AP10: 0 | AQ10: 0 | AR10: 0 | AS10: 0 | AT10: 0 | AU10: 0 | AV10: 0 | AW10: 0 | AX10: 0 | AY10: 0 | AZ10: 0 | BA10: 0 | BB10: 0 | BC10: 0 | BD10: 0 | BE10: 0 | BF10: 0 | BG10: 0 | BH10: 0 | BI10: 0 | BJ10: 0 | BK10: 0 | BL10: 0 | BM10: 0 | BN10: 0 | BO10: 0 | BP10: 0 | BQ10: 0 | BR10: 0 | BS10: 0 | BT10: 0 | BU10: 0 | BV10: 0 | BW10: 0 | BX10: 0 | BY10: 0 | BZ10: 0 | CA10: 0 | CB10: 0 | CC10: 0 | CD10: 0 | CE10: 0 | CF10: 0 | CG10: 0 | CH10: 0 | CI10: 0 | CJ10: 0 | CK10: 0 | CL10: 0 | CM10: 0 | CN10: 0 | CO10: 0 | CP10: 0 | CQ10: 0 | CR10: 0 | CS10: 0 | CT10: 0 | CU10: 0 | CV10: 0 | CW10: 0 | CX10: 0 | CY10: 0 | CZ10: 0 | DA10: 0 | DB10: 0 | DC10: 0 | DD10: 0 | DE10: 0 | DF10: 0 | DG10: 0 | DH10: 0 | DI10: 0 | DJ10: 0 | DK10: 0 | DL10: 0 | DM10: 0 | DN10: 0 | DO10: 0 | DP10: 0 | DQ10: 0 | DR10: 0 | DS10: 0 | DT10: 0 | DU10: 0 | DV10: 0 | DW10: 0 | DX10: 0 | DY10: 0 | DZ10: 0 | EA10: 0 | EB10: 0 | EC10: 0 | ED10: 0 | EE10: 0 | EF10: 0 | EG10: 0 | EH10: 0 | EI10: 0 | EJ10: 0 | EK10: 0 | EL10: 0 | EM10: 0 | EN10: 0 | EO10: 0 | EP10: 0 | EQ10: 0 | ER10: 0 | ES10: 0 | ET10: 0 | EU10: 0 | EV10: 0 | EW10: 0 | EX10: 0 | EY10: 0 | EZ10: 0 | FA10: 0 | FB10: 0 | FC10: 0 | FD10: 0 | FE10: 0 | FF10: 0 | FG10: 0 | FH10: 0 | FI10: 0 | FJ10: 0 | FK10: 0 | FL10: 0 | FM10: 0 | FN10: 0 | FO10: 0 | FP10: 0 | FQ10: 0 | FR10: 0 | FS10: 0 | FT10: 0 | FU10: 0 | FV10: 0 | FW10: 0 | FX10: 0 | FY10: 0 | FZ10: 0 | GA10: 0 | GB10: 0 | GC10: 0 | GD10: 0 | GE10: 0 | GF10: 0 | GG10: 0 | GH10: 0 | GI10: 0 | GJ10: 0 | GK10: 0 | GL10: 0 | GM10: 0 | GN10: 0 | GO10: 0 | GP10: 0 | GQ10: 0 | GR10: 0 | GS10: 0 | GT10: 0 | GU10: 0 | GV10: 0 | GW10: 0 | GX10: 0 | GY10: 0 | GZ10: 0 | HA10: 0 | HB10: 0 | HC10: 0 | HD10: 0 | HE10: 0 | HF10: 0 | HG10: 0 | HH10: 0 | HI10: 0 | HJ10: 0 | HK10: 0 | HL10: 0 | HM10: 0 | HN10: 0 | HO10: 0 | HP10: 0 | HQ10: 0 | HR10: 0 | HS10: 0 | HT10: 0 | HU10: 0 | HV10: 0 | HW10: 0 | HX10: 0 | HY10: 0 | HZ10: 0 | IA10: 0 | IB10: 0 | IC10: 0 | ID10: 0 | IE10: 0 | IF10: 0 | IG10: 0 | IH10: 0 | II10: 0 | IJ10: 0 | IK10: 0 | IL10: 0 | IM10: 0 | IN10: 0 | IO10: 0 | IP10: 0 | IQ10: 0 | IR10: 0 | IS10: 0 | IT10: 0 | IU10: 0 | IV10: 0
A11: 0 | B11: 0 | C11: 0 | D11: 0 | E11: 0 | F11: 0 | G11: 0 | H11: 0 | I11: 0 | J11: 0 | K11: 0 | L11: 0 | M11: 0 | N11: 0 | O11: 0 | P11: 0 | Q11: 0 | R11: 0 | S11: 0 | T11: 0 | U11: 0 | V11: 0 | W11: 0 | X11: 0 | Y11: 0 | Z11: 0 | AA11: 0 | AB11: 0 | AC11: 0 | AD11: 0 | AE11: 0 | AF11: 0 | AG11: 0 | AH11: 0 | AI11: 0 | AJ11: 0 | AK11: 0 | AL11: 0 | AM11: 0 | AN11: 0 | AO11: 0 | AP11: 0 | AQ11: 0 | AR11: 0 | AS11: 0 | AT11: 0 | AU11: 0 | AV11: 0 | AW11: 0 | AX11: 0 | AY11: 0 | AZ11: 0 | BA11: 0 | BB11: 0 | BC11: 0 | BD11: 0 | BE11: 0 | BF11: 0 | BG11: 0 | BH11: 0 | BI11: 0 | BJ11: 0 | BK11: 0 | BL11: 0 | BM11: 0 | BN11: 0 | BO11: 0 | BP11: 0 | BQ11: 0 | BR11: 0 | BS11: 0 | BT11: 0 | BU11: 0 | BV11: 0 | BW11: 0 | BX11: 0 | BY11: 0 | BZ11: 0 | CA11: 0 | CB11: 0 | CC11: 0 | CD11: 0 | CE11: 0 | CF11: 0 | CG11: 0 | CH11: 0 | CI11: 0 | CJ11: 0 | CK11: 0 | CL11: 0 | CM11: 0 | CN11: 0 | CO11: 0 | CP11: 0 | CQ11: 0 | CR11: 0 | CS11: 0 | CT11: 0 | CU11: 0 | CV11: 0 | CW11: 0 | CX11: 0 | CY11: 0 | CZ11: 0 | DA11: 0 | DB11: 0 | DC11: 0 | DD11: 0 | DE11: 0 | DF11: 0 | DG11: 0 | DH11: 0 | DI11: 0 | DJ11: 0 | DK11: 0 | DL11: 0 | DM11: 0 | DN11: 0 | DO11: 0 | DP11: 0 | DQ11: 0 | DR11: 0 | DS11: 0 | DT11: 0 | DU11: 0 | DV11: 0 | DW11: 0 | DX11: 0 | DY11: 0 | DZ11: 0 | EA11: 0 | EB11: 0 | EC11: 0 | ED11: 0 | EE11: 0 | EF11: 0 | EG11: 0 | EH11: 0 | EI11: 0 | EJ11: 0 | EK11: 0 | EL11: 0 | EM11: 0 | EN11: 0 | EO11: 0 | EP11: 0 | EQ11: 0 | ER11: 0 | ES11: 0 | ET11: 0 | EU11: 0 | EV11: 0 | EW11: 0 | EX11: 0 | EY11: 0 | EZ11: 0 | FA11: 0 | FB11: 0 | FC11: 0 | FD11: 0 | FE11: 0 | FF11: 0 | FG11: 0 | FH11: 0 | FI11: 0 | FJ11: 0 | FK11: 0 | FL11: 0 | FM11: 0 | FN11: 0 | FO11: 0 | FP11: 0 | FQ11: 0 | FR11: 0 | FS11: 0 | FT11: 0 | FU11: 0 | FV11: 0 | FW11: 0 | FX11: 0 | FY11: 0 | FZ11: 0 | GA11: 0 | GB11: 0 | GC11: 0 | GD11: 0 | GE11: 0 | GF11: 0 | GG11: 0 | GH11: 0 | GI11: 0 | GJ11: 0 | GK11: 0 | GL11: 0 | GM11: 0 | GN11: 0 | GO11: 0 | GP11: 0 | GQ11: 0 | GR11: 0 | GS11: 0 | GT11: 0 | GU11: 0 | GV11: 0 | GW11: 0 | GX11: 0 | GY11: 0 | GZ11: 0 | HA11: 0 | HB11: 0 | HC11: 0 | HD11: 0 | HE11: 0 | HF11: 0 | HG11: 0 | HH11: 0 | HI11: 0 | HJ11: 0 | HK11: 0 | HL11: 0 | HM11: 0 | HN11: 0 | HO11: 0 | HP11: 0 | HQ11: 0 | HR11: 0 | HS11: 0 | HT11: 0 | HU11: 0 | HV11: 0 | HW11: 0 | HX11: 0 | HY11: 0 | HZ11: 0 | IA11: 0 | IB11: 0 | IC11: 0 | ID11: 0 | IE11: 0 | IF11: 0 | IG11: 0 | IH11: 0 | II11: 0 | IJ11: 0 | IK11: 0 | IL11: 0 | IM11: 0 | IN11: 0 | IO11: 0 | IP11: 0 | IQ11: 0 | IR11: 0 | IS11: 0 | IT11: 0 | IU11: 0 | IV11: 0
A12: 0 | B12: 0 | C12: 0 | D12: 0 | E12: 0 | F12: 0 | G12: 0 | H12: 0 | I12: 0 | J12: 0 | K12: 0 | L12: 0 | M12: 0 | N12: 0 | O12: 0 | P12: 0 | Q12: 0 | R12: 0 | S12: 0 | T12: 0 | U12: 0 | V12: 0 | W12: 0 | X12: 0 | Y12: 0 | Z12: 0 | AA12: 0 | AB12: 0 | AC12: 0 | AD12: 0 | AE12: 0 | AF12: 0 | AG12: 0 | AH12: 0 | AI12: 0 | AJ12: 0 | AK12: 0 | AL12: 0 | AM12: 0 | AN12: 0 | AO12: 0 | AP12: 0 | AQ12: 0 | AR12: 0 | AS12: 0 | AT12: 0 | AU12: 0 | AV12: 0 | AW12: 0 | AX12: 0 | AY12: 0 | AZ12: 0 | BA12: 0 | BB12: 0 | BC12: 0 | BD12: 0 | BE12: 0 | BF12: 0 | BG12: 0 | BH12: 0 | BI12: 0 | BJ12: 0 | BK12: 0 | BL12: 0 | BM12: 0 | BN12: 0 | BO12: 0 | BP12: 0 | BQ12: 0 | BR12: 0 | BS12: 0 | BT12: 0 | BU12: 0 | BV12: 0 | BW12: 0 | BX12: 0 | BY12: 0 | BZ12: 0 | CA12: 0 | CB12: 0 | CC12: 0 | CD12: 0 | CE12: 0 | CF12: 0 | CG12: 0 | CH12: 0 | CI12: 0 | CJ12: 0 | CK12: 0 | CL12: 0 | CM12: 0 | CN12: 0 | CO12: 0 | CP12: 0 | CQ12: 0 | CR12: 0 | CS12: 0 | CT12: 0 | CU12: 0 | CV12: 0 | CW12: 0 | CX12: 0 | CY12: 0 | CZ12: 0 | DA12: 0 | DB12: 0 | DC12: 0 | DD12: 0 | DE12: 0 | DF12: 0 | DG12: 0 | DH12: 0 | DI12: 0 | DJ12: 0 | DK12: 0 | DL12: 0 | DM12: 0 | DN12: 0 | DO12: 0 | DP12: 0 | DQ12: 0 | DR12: 0 | DS12: 0 | DT12: 0 | DU12: 0 | DV12: 0 | DW12: 0 | DX12: 0 | DY12: 0 | DZ12: 0 | EA12: 0 | EB12: 0 | EC12: 0 | ED12: 0 | EE12: 0 | EF12: 0 | EG12: 0 | EH12: 0 | EI12: 0 | EJ12: 0 | EK12: 0 | EL12: 0 | EM12: 0 | EN12: 0 | EO12: 0 | EP12: 0 | EQ12: 0 | ER12: 0 | ES12: 0 | ET12: 0 | EU12: 0 | EV12: 0 | EW12: 0 | EX12: 0 | EY12: 0 | EZ12: 0 | FA12: 0 | FB12: 0 | FC12: 0 | FD12: 0 | FE12: 0 | FF12: 0 | FG12: 0 | FH12: 0 | FI12: 0 | FJ12: 0 | FK12: 0 | FL12: 0 | FM12: 0 | FN12: 0 | FO12: 0 | FP12: 0 | FQ12: 0 | FR12: 0 | FS12: 0 | FT12: 0 | FU12: 0 | FV12: 0 | FW12: 0 | FX12: 0 | FY12: 0 | FZ12: 0 | GA12: 0 | GB12: 0 | GC12: 0 | GD12: 0 | GE12: 0 | GF12: 0 | GG12: 0 | GH12: 0 | GI12: 0 | GJ12: 0 | GK12: 0 | GL12: 0 | GM12: 0 | GN12: 0 | GO12: 0 | GP12: 0 | GQ12: 0 | GR12: 0 | GS12: 0 | GT12: 0 | GU12: 0 | GV12: 0 | GW12: 0 | GX12: 0 | GY12: 0 | GZ12: 0 | HA12: 0 | HB12: 0 | HC12: 0 | HD12: 0 | HE12: 0 | HF12: 0 | HG12: 0 | HH12: 0 | HI12: 0 | HJ12: 0 | HK12: 0 | HL12: 0 | HM12: 0 | HN12: 0 | HO12: 0 | HP12: 0 | HQ12: 0 | HR12: 0 | HS12: 0 | HT12: 0 | HU12: 0 | HV12: 0 | HW12: 0 | HX12: 0 | HY12: 0 | HZ12: 0 | IA12: 0 | IB12: 0 | IC12: 0 | ID12: 0 | IE12: 0 | IF12: 0 | IG12: 0 | IH12: 0 | II12: 0 | IJ12: 0 | IK12: 0 | IL12: 0 | IM12: 0 | IN12: 0 | IO12: 0 | IP12: 0 | IQ12: 0 | IR12: 0 | IS12: 0 | IT12: 0 | IU12: 0 | IV12: 0
... A256: 0 | B256: 0 | C256: 0 | D256: 0 | E256: 0 | F256: 0 | G256: 0 | H256: 0 | I256: 0 | J256: 0 | K256: 0 | L256: 0 | M256: 0 | N256: 0 | O256: 0 | P256: 0 | Q256: 0 | R256: 0 | S256: 0 | T256: 0 | U256: 0 | V256: 0 | W256: 0 | X256: 0 | Y256: 0 | Z256: 0 | AA256: 0 | AB256: 0 | AC256: 0 | AD256: 0 | AE256: 0 | AF256: 0 | AG256: 0 | AH256: 0 | AI256: 0 | AJ256: 0 | AK256: 0 | AL256: 0 | AM256: 0 | AN256: 0 | AO256: 0 | AP256: 0 | AQ256: 0 | AR256: 0 | AS256: 0 | AT256: 0 | AU256: 0 | AV256: 0 | AW256: 0 | AX256: 0 | AY256: 0 | AZ256: 0 | BA256: 0 | BB256: 0 | BC256: 0 | BD256: 0 | BE256: 0 | BF256: 0 | BG256: 0 | BH256: 0 | BI256: 0 | BJ256: 0 | BK256: 0 | BL256: 0 | BM256: 0 | BN256: 0 | BO256: 0 | BP256: 0 | BQ256: 0 | BR256: 0 | BS256: 0 | BT256: 0 | BU256: 0 | BV256: 0 | BW256: 0 | BX256: 0 | BY256: 0 | BZ256: 0 | CA256: 0 | CB256: 0 | CC256: 0 | CD256: 0 | CE256: 0 | CF256: 0 | CG256: 0 | CH256: 0 | CI256: 0 | CJ256: 0 | CK256: 0 | CL256: 0 | CM256: 0 | CN256: 0 | CO256: 0 | CP256: 0 | CQ256: 0 | CR256: 0 | CS256: 0 | CT256: 0 | CU256: 0 | CV256: 0 | CW256: 0 | CX256: 0 | CY256: 0 | CZ256: 0 | DA256: 0 | DB256: 0 | DC256: 0 | DD256: 0 | DE256: 0 | DF256: 0 | DG256: 0 | DH256: 0 | DI256: 0 | DJ256: 0 | DK256: 0 | DL256: 0 | DM256: 0 | DN256: 0 | DO256: 0 | DP256: 0 | DQ256: 0 | DR256: 0 | DS256: 0 | DT256: 0 | DU256: 0 | DV256: 0 | DW256: 0 | DX256: 0 | DY256: 0 | DZ256: 0 | EA256: 0 | EB256: 0 | EC256: 0 | ED256: 0 | EE256: 0 | EF256: 0 | EG256: 0 | EH256: 0 | EI256: 0 | EJ256: 0 | EK256: 0 | EL256: 0 | EM256: 0 | EN256: 0 | EO256: 0 | EP256: 0 | EQ256: 0 | ER256: 0 | ES256: 0 | ET256: 0 | EU256: 0 | EV256: 0 | EW256: 0 | EX256: 0 | EY256: 0 | EZ256: 0 | FA256: 0 | FB256: 0 | FC256: 0 | FD256: 0 | FE256: 0 | FF256: 0 | FG256: 0 | FH256: 0 | FI256: 0 | FJ256: 0 | FK256: 0 | FL256: 0 | FM256: 0 | FN256: 0 | FO256: 0 | FP256: 0 | FQ256: 0 | FR256: 0 | FS256: 0 | FT256: 0 | FU256: 0 | FV256: 0 | FW256: 0 | FX256: 0 | FY256: 0 | FZ256: 0 | GA256: 0 | GB256: 0 | GC256: 0 | GD256: 0 | GE256: 0 | GF256: 0 | GG256: 0 | GH256: 0 | GI256: 0 | GJ256: 0 | GK256: 0 | GL256: 0 | GM256: 0 | GN256: 0 | GO256: 0 | GP256: 0 | GQ256: 0 | GR256: 0 | GS256: 0 | GT256: 0 | GU256: 0 | GV256: 0 | GW256: 0 | GX256: 0 | GY256: 0 | GZ256: 0 | HA256: 0 | HB256: 0 | HC256: 0 | HD256: 0 | HE256: 0 | HF256: 0 | HG256: 0 | HH256: 0 | HI256: 0 | HJ256: 0 | HK256: 0 | HL256: 0 | HM256: 0 | HN256: 0 | HO256: 0 | HP256: 0 | HQ256: 0 | HR256: 0 | HS256: 0 | HT256: 0 | HU256: 0 | HV256: 0 | HW256: 0 | HX256: 0 | HY256: 0 | HZ256: 0 | IA256: 0 | IB256: 0 | IC256: 0 | ID256: 0 | IE256: 0 | IF256: 0 | IG256: 0 | IH256: 0 | II256: 0 | IJ256: 0 | IK256: 0 | IL256: 0 | IM256: 0 | IN256: 0 | IO256: 0 | IP256: 0 | IQ256: 0 | IR256: 0 | IS256: 0 | IT256: 0 | IU256: 0 | IV256: 0
A257: 0 | B257: 0 | C257: 0 | D257: 0 | E257: 0 | F257: 0 | G257: 0 | H257: 0 | I257: 0 | J257: 0 | K257: 0 | L257: 0 | M257: 0 | N257: 0 | O257: 0 | P257: 0 | Q257: 0 | R257: 0 | S257: 0 | T257: 0 | U257: 0 | V257: 0 | W257: 0 | X257: 0 | Y257: 0 | Z257: 0 | AA257: 0 | AB257: 0 | AC257: 0 | AD257: 0 | AE257: 0 | AF257: 0 | AG257: 0 | AH257: 0 | AI257: 0 | AJ257: 0 | AK257: 0 | AL257: 0 | AM257: 0 | AN257: 0 | AO257: 0 | AP257: 0 | AQ257: 0 | AR257: 0 | AS257: 0 | AT257: 0 | AU257: 0 | AV257: 0 | AW257: 0 | AX257: 0 | AY257: 0 | AZ257: 0 | BA257: 0 | BB257: 0 | BC257: 0 | BD257: 0 | BE257: 0 | BF257: 0 | BG257: 0 | BH257: 0 | BI257: 0 | BJ257: 0 | BK257: 0 | BL257: 0 | BM257: 0 | BN257: 0 | BO257: 0 | BP257: 0 | BQ257: 0 | BR257: 0 | BS257: 0 | BT257: 0 | BU257: 0 | BV257: 0 | BW257: 0 | BX257: 0 | BY257: 0 | BZ257: 0 | CA257: 0 | CB257: 0 | CC257: 0 | CD257: 0 | CE257: 0 | CF257: 0 | CG257: 0 | CH257: 0 | CI257: 0 | CJ257: 0 | CK257: 0 | CL257: 0 | CM257: 0 | CN257: 0 | CO257: 0 | CP257: 0 | CQ257: 0 | CR257: 0 | CS257: 0 | CT257: 0 | CU257: 0 | CV257: 0 | CW257: 0 | CX257: 0 | CY257: 0 | CZ257: 0 | DA257: 0 | DB257: 0 | DC257: 0 | DD257: 0 | DE257: 0 | DF257: 0 | DG257: 0 | DH257: 0 | DI257: 0 | DJ257: 0 | DK257: 0 | DL257: 0 | DM257: 0 | DN257: 0 | DO257: 0 | DP257: 0 | DQ257: 0 | DR257: 0 | DS257: 0 | DT257: 0 | DU257: 0 | DV257: 0 | DW257: 0 | DX257: 0
A258: 0 | B258: 0 | C258: 0 | D258: 0 | E258: 0 | F258: 0 | G258: 0 | H258: 0 | I258: 0 | J258: 0 | K258: 0 | L258: 0 | M258: 0 | N258: 0 | O258: 0 | P258: 0 | Q258: 0 | R258: 0 | S258: 0 | T258: 0 | U258: 0 | V258: 0 | W258: 0 | X258: 0 | Y258: 0 | Z258: 0 | AA258: 0 | AB258: 0 | AC258: 0 | AD258: 0 | AE258: 0 | AF258: 0 | AG258: 0 | AH258: 0 | AI258: 0 | AJ258: 0 | AK258: 0 | AL258: 0 | AM258: 0 | AN258: 0 | AO258: 0 | AP258: 0 | AQ258: 0 | AR258: 0 | AS258: 0 | AT258: 0 | AU258: 0 | AV258: 0 | AW258: 0 | AX258: 0 | AY258: 0 | AZ258: 0 | BA258: 0 | BB258: 0 | BC258: 0 | BD258: 0 | BE258: 0 | BF258: 0 | BG258: 0 | BH258: 0 | BI258: 0 | BJ258: 0 | BK258: 0 | BL258: 0 | BM258: 0 | BN258: 0 | BO258: 0 | BP258: 0 | BQ258: 0 | BR258: 0 | BS258: 0 | BT258: 0 | BU258: 0 | BV258: 0 | BW258: 0 | BX258: 0 | BY258: 0 | BZ258: 0 | CA258: 0 | CB258: 0 | CC258: 0 | CD258: 0 | CE258: 0 | CF258: 0 | CG258: 0 | CH258: 0 | CI258: 0 | CJ258: 0 | CK258: 0 | CL258: 0 | CM258: 0 | CN258: 0 | CO258: 0 | CP258: 0 | CQ258: 0 | CR258: 0 | CS258: 0 | CT258: 0 | CU258: 0 | CV258: 0 | CW258: 0 | CX258: 0 | CY258: 0 | CZ258: 0 | DA258: 0 | DB258: 0 | DC258: 0 | DD258: 0 | DE258: 0 | DF258: 0 | DG258: 0 | DH258: 0 | DI258: 0 | DJ258: 0 | DK258: 0 | DL258: 0 | DM258: 0 | DN258: 0 | DO258: 0 | DP258: 0 | DQ258: 0 | DR258: 0 | DS258: 0 | DT258: 0 | DU258: 0 | DV258: 0 | DW258: 0 | DX258: 0
A259: 0 | B259: 0 | C259: 0 | D259: 0 | E259: 0 | F259: 0 | G259: 0 | H259: 0 | I259: 0 | J259: 0 | K259: 0 | L259: 0 | M259: 0 | N259: 0 | O259: 0 | P259: 0 | Q259: 0 | R259: 0 | S259: 0 | T259: 0 | U259: 0 | V259: 0 | W259: 0 | X259: 0 | Y259: 0 | Z259: 0 | AA259: 0 | AB259: 0 | AC259: 0 | AD259: 0 | AE259: 0 | AF259: 0 | AG259: 0 | AH259: 0 | AI259: 0 | AJ259: 0 | AK259: 0 | AL259: 0 | AM259: 0 | AN259: 0 | AO259: 0 | AP259: 0 | AQ259: 0 | AR259: 0 | AS259: 0 | AT259: 0 | AU259: 0 | AV259: 0 | AW259: 0 | AX259: 0 | AY259: 0 | AZ259: 0 | BA259: 0 | BB259: 0 | BC259: 0 | BD259: 0 | BE259: 0 | BF259: 0 | BG259: 0 | BH259: 0 | BI259: 0 | BJ259: 0 | BK259: 0 | BL259: 0 | BM259: 0 | BN259: 0 | BO259: 0 | BP259: 0 | BQ259: 0 | BR259: 0 | BS259: 0 | BT259: 0 | BU259: 0 | BV259: 0 | BW259: 0 | BX259: 0 | BY259: 0 | BZ259: 0 | CA259: 0 | CB259: 0 | CC259: 0 | CD259: 0 | CE259: 0 | CF259: 0 | CG259: 0 | CH259: 0 | CI259: 0 | CJ259: 0 | CK259: 0 | CL259: 0 | CM259: 0 | CN259: 0 | CO259: 0 | CP259: 0 | CQ259: 0 | CR259: 0 | CS259: 0 | CT259: 0 | CU259: 0 | CV259: 0 | CW259: 0 | CX259: 0 | CY259: 0 | CZ259: 0 | DA259: 0 | DB259: 0 | DC259: 0 | DD259: 0 | DE259: 0 | DF259: 0 | DG259: 0 | DH259: 0 | DI259: 0 | DJ259: 0 | DK259: 0 | DL259: 0 | DM259: 0 | DN259: 0 | DO259: 0 | DP259: 0 | DQ259: 0 | DR259: 0 | DS259: 0 | DT259: 0 | DU259: 0 | DV259: 0 | DW259: 0 | DX259: 0
